Workbook

Sheet 250505_these Lisa_sol_cinetique
A1: Quantify Compound Summary Report
A3: Printed Wed May 07 15:55:28 2025
A5: Compound 1: Diflufenican
B7: # | C7: Name | D7: Sample Text | E7: RT | F7: Type | G7: Std, Conc | H7: %Dev | I7: Primary Flags | J7: µg/l | K7: Area | L7: IS Area | M7: Response | N7: 1ｺ Area | O7: S/N | P7: 1ｺ Ratio (Actual)
A8: 1 | B8: 1 | C8: 250505_gamme_015ugL_1 | E8: 9.02 | F8: Standard | G8: 0.15 | H8: 2 | I8: bb | J8: 0.1531 | K8: 570 | L8: 112567 | M8: 1.013 | N8: 205 | O8: 299.171 | P8: 2.777
A9: 2 | B9: 2 | C9: 250505_gamme_050ugL_1 | E9: 9.02 | F9: Standard | G9: 0.5 | H9: 0.1 | I9: bb | J9: 0.5003 | K9: 1919 | L9: 116098 | M9: 3.306 | N9: 582 | O9: 720.438 | P9: 3.299
A10: 3 | B10: 3 | C10: 250505_gamme_2ugL_1 | E10: 9.02 | F10: Standard | G10: 2 | H10: -2.9 | I10: bb | J10: 1.9412 | K10: 8208 | L10: 128045 | M10: 12.821 | N10: 2435 | O10: 5360.97 | P10: 3.371
A11: 4 | B11: 4 | C11: 250505_gamme_20ugL_1 | E11: 9.02 | F11: Standard | G11: 20.1 | H11: 2.8 | I11: bb | J11: 20.653 | K11: 90009 | L11: 132398 | M11: 135.967 | N11: 25039 | O11: 74997.06 | P11: 3.595
A12: 5 | B12: 5 | C12: 250505_gamme_50ugL_1 | E12: 9.01 | F12: Standard | G12: 50.2 | H12: 0.2 | I12: bb | J12: 50.3143 | K12: 227726 | L12: 138172 | M12: 329.628 | N12: 63090 | O12: 247249.62 | P12: 3.609
A13: 6 | B13: 6 | C13: 250505_gamme_100ugL_1 | E13: 9.01 | F13: Standard | G13: 100.4 | H13: 0.1 | I13: bb | J13: 100.5385 | K13: 459398 | L13: 140658 | M13: 653.215 | N13: 127721 | O13: 130029.77 | P13: 3.597
A14: 7 | B14: 7 | C14: 250505_gamme_300ugL_1 | E14: 9.01 | F14: Standard | G14: 301.2 | H14: 4.4 | I14: bb | J14: 314.4619 | K14: 1449844 | L14: 147154 | M14: 1970.512 | N14: 404538 | O14: 1460835.3 | P14: 3.584
A15: 27 | B15: 27 | C15: 250505_gamme_015ugL_2 | E15: 9.02 | F15: Standard | G15: 0.15 | H15: -1.7 | I15: bb | J15: 0.1475 | K15: 777 | L15: 159209 | M15: 0.976 | N15: 273 | O15: 1835.327 | P15: 2.843
A16: 28 | B16: 28 | C16: 250505_gamme_050ugL_2 | E16: 9.02 | F16: Standard | G16: 0.5 | H16: 0.7 | I16: bb | J16: 0.5037 | K16: 2613 | L16: 157012 | M16: 3.329 | N16: 805 | O16: 1336.556 | P16: 3.247
A17: 29 | B17: 29 | C17: 250505_gamme_2ugL_2 | E17: 9.01 | F17: Standard | G17: 2 | H17: -0.8 | I17: bb | J17: 1.9847 | K17: 10031 | L17: 153061 | M17: 13.107 | N17: 2955 | O17: 5062.369 | P17: 3.395
A18: 30 | B18: 30 | C18: 250505_gamme_20ugL_2 | E18: 9.01 | F18: Standard | G18: 20.1 | H18: 1.1 | I18: bb | J18: 20.3257 | K18: 102975 | L18: 153900 | M18: 133.82 | N18: 29497 | O18: 43176.15 | P18: 3.491
A19: 31 | B19: 31 | C19: 250505_gamme_50ugL_2 | E19: 9.01 | F19: Standard | G19: 50.2 | H19: -1.3 | I19: bb | J19: 49.5473 | K19: 255626 | L19: 157481 | M19: 324.644 | N19: 74169 | O19: 297241.11 | P19: 3.447
A20: 32 | B20: 32 | C20: 250505_gamme_100ugL_2 | E20: 9.01 | F20: Standard | G20: 100.4 | H20: -0.5 | I20: bb | J20: 99.9336 | K20: 505080 | L20: 155565 | M20: 649.35 | N20: 143936 | O20: 156887.09 | P20: 3.509
A21: 33 | B21: 33 | C21: 250505_gamme_300ugL_2 | E21: 9.01 | F21: Standard | G21: 301.2 | H21: -4.3 | I21: bb | J21: 288.1592 | K21: 1527659 | L21: 168442 | M21: 1813.87 | N21: 443355 | O21: 234638.33 | P21: 3.446 | R21: prise d'essai (g) | S21: quantité extrait (µg) | T21: mg/kg | U21: RDT SI %
A22: 12 | B22: 12 | C22: 250505_EPX_J21_1 | E22: 9.01 | F22: Analyte | I22: bb | J22: 539.2071 | K22: 289 | L22: 18 | M22: 3248.059 | N22: 76 | O22: 63.496 | P22: 3.807 | R22: 4.964 | U22: pas de standard interne
A23: 13 | B23: 13 | C23: 250505_EPX_J14_3 | E23: 9.01 | F23: Analyte | I23: bb | J23: 340.8252 | K23: 226 | L23: 21 | M23: 2126.016 | N23: 90 | O23: 195.297 | P23: 2.513 | R23: 5.0912 | U23: pas de standard interne
A24: 14 | B24: 14 | C24: 250505_EPX_J7_1 | E24: 9.01 | F24: Analyte | I24: bb | K24: 161 | N24: 42 | O24: 23.514 | P24: 3.818 | R24: 4.9481 | U24: pas de standard interne
A25: 15 | B25: 15 | C25: 250505_EPX_J0_1 | E25: 9.01 | F25: Analyte | I25: bb | J25: 368.2206 | K25: 407 | L25: 36 | M25: 2286.018 | N25: 108 | O25: 93.173 | P25: 3.76 | R25: 5.0441 | U25: pas de standard interne
A26: 16 | B26: 16 | C26: 250505_EPX_J0_2 | E26: 9.01 | F26: Analyte | I26: bb | J26: 411.0927 | K26: 196 | L26: 16 | M26: 2533.161 | N26: 51 | O26: 79.618 | P26: 3.873 | R26: 5.0977 | U26: pas de standard interne
A27: 17 | B27: 17 | C27: 250505_epx_J14_3_dil20 | E27: 9.01 | F27: Analyte | I27: bb | K27: 101 | N27: 41 | O27: 70.547 | P27: 2.461 | R27: 5.0912 | U27: pas de standard interne
A28: 18 | B28: 18 | C28: 250505_IMD_J21_1 | E28: 9.01 | F28: Analyte | I28: bb | J28: 1.2373 | K28: 1694 | L28: 41452 | M28: 8.173 | N28: 514 | O28: 395.811 | P28: 3.296 | R28: 5.0968 | S28: =(J28*2/1000)*9/8 -> 0.002783925 | T28: =(S28*1000/5)/1000 -> 0.000556785 | U28: =100+H65 -> 28.7
A29: 19 | B29: 19 | C29: 250505_IMD_J14_3 | E29: 9.01 | F29: Analyte | I29: bb | J29: 0.7497 | K29: 1042 | L29: 42052 | M29: 4.953 | N29: 312 | O29: 548.865 | P29: 3.335 | R29: 5.037 | S29: =(J29*2/1000)*9/8 -> 0.001686825 | T29: =(S29*1000/5)/1000 -> 0.000337365 | U29: =100+H66 -> 29.1
A30: 20 | B30: 20 | C30: 250505_IND_J7_1 | E30: 9 | F30: Analyte | I30: bb | J30: 0.4326 | K30: 628 | L30: 43953 | M30: 2.86 | N30: 202 | O30: 208.329 | P30: 3.104 | R30: 5.0721 | S30: =(J30*2/1000)*9/8 -> 0.00097335 | T30: =(S30*1000/5)/1000 -> 0.00019467 | U30: =100+H67 -> 30.5
A31: 21 | B31: 21 | C31: 250505_IMD_J0_1 | E31: 9 | F31: Analyte | I31: bb | J31: 0.8324 | K31: 1383 | L31: 50285 | M31: 5.5 | N31: 419 | O31: 327.958 | P31: 3.3 | R31: 4.9245 | S31: =(J31*2/1000)*9/8 -> 0.0018729 | T31: =(S31*1000/5)/1000 -> 0.00037458 | U31: =100+H68 -> 34.9
A32: 22 | B32: 22 | C32: 250505_IMD_J0_2 | E32: 9 | F32: Analyte | I32: bb | J32: 0.4839 | K32: 870 | L32: 54382 | M32: 3.198 | N32: 261 | O32: 700.933 | P32: 3.338 | R32: 4.9744 | S32: =(J32*2/1000)*9/8 -> 0.001088775 | T32: =(S32*1000/5)/1000 -> 0.000217755 | U32: =100+H69 -> 37.7
A33: 8 | B33: 8 | C33: 250505_blanc_MeOH_1 | E33: 9.02 | I33: bb | J33: 241.1023 | K33: 905 | L33: 118 | M33: 1529.906 | N33: 244 | O33: 91.87 | P33: 3.716
A34: 9 | B34: 9 | C34: 250505_blanc3 | E34: 9.02 | I34: bb | J34: 186.6944 | K34: 306 | L34: 51 | M34: 1195.624 | N34: 73 | O34: 137.808 | P34: 4.196
A35: 10 | B35: 10 | C35: 250505_blanc4 | E35: 9.02 | I35: bb | K35: 153 | N35: 53 | O35: 191.326 | P35: 2.898
A36: 11 | B36: 11 | C36: 250505_blanc5 | E36: 9.01 | I36: bb | K36: 120 | O36: 22.627
A37: 23 | B37: 23 | C37: 250505_blanc_MeOH_2 | L37: 59
A38: 24 | B38: 24 | C38: 250505_blanc6
A39: 25 | B39: 25 | C39: 250505_blanc7
A40: 26 | B40: 26 | C40: 250505_blanc8
A42: Compound 2: Diflufenican-d3
B44: # | C44: Name | D44: Sample Text | E44: RT | F44: Type | G44: Std, Conc | H44: %Dev | I44: Primary Flags | J44: µg/l | K44: Area | L44: IS Area | M44: Response | N44: 1ｺ Area | O44: S/N | P44: 1ｺ Ratio (Actual)
A45: 1 | B45: 1 | C45: 250505_gamme_015ugL_1 | E45: 9.01 | F45: Standard | G45: 200 | H45: -22 | I45: MM | J45: 156.0519 | K45: 112567 | M45: 112566.98 | O45: 68512.931
...

Sheet 250513_these Lisa_sol_cinetique
A1: Quantify Compound Summary Report
A3: Printed Thu May 15 15:00:37 2025
A5: Compound 1: Diflufenican
B7: # | C7: Name | D7: Sample Text | E7: RT | F7: Type | G7: Std, Conc | H7: %Dev | I7: Primary Flags | J7: ng/l | K7: Area | L7: IS Area | M7: Response | N7: 1ｺ Area | O7: S/N | P7: 1ｺ Ratio (Actual)
A8: 1 | B8: 1 | C8: 250513_gamme1_4 | E8: 12.19 | F8: Standard | G8: 40 | H8: -26.2 | I8: bb | J8: 29.532 | K8: 7953 | L8: 22007 | M8: 469.765 | N8: 2232 | O8: 1363.376 | P8: 3.563
A9: 2 | B9: 2 | C9: 250513_gamme2 | E9: 12.19 | F9: Standard | G9: 110 | H9: 12 | I9: bb | J9: 123.2455 | K9: 22413 | L9: 23996 | M9: 1214.191 | N9: 6531 | O9: 2329.079 | P9: 3.432
A10: 3 | B10: 3 | C10: 250513_gamme3 | E10: 12.19 | F10: Standard | G10: 200 | H10: -0.3 | I10: bb | J10: 199.4633 | K10: 41612 | L10: 29668 | M10: 1823.342 | N10: 11799 | O10: 2137.24 | P10: 3.527
A11: 4 | B11: 4 | C11: 250513_gamme4 | E11: 12.19 | F11: Standard | G11: 540 | H11: -6.3 | I11: bb | J11: 505.779 | K11: 114116 | L11: 34460 | M11: 4305 | N11: 33016 | O11: 10887.142 | P11: 3.456
A12: 5 | B12: 5 | C12: 250513_gamme5 | E12: 12.18 | F12: Standard | G12: 1000 | H12: -10.8 | I12: bb | J12: 891.9112 | K12: 184788 | L12: 31988 | M12: 7509.768 | N12: 53669 | O12: 24798.243 | P12: 3.443
A13: 6 | B13: 6 | C13: 250513_gamme6 | E13: 12.18 | F13: Standard | G13: 2000 | H13: -15.3 | I13: bb | J13: 1694.826 | K13: 370955 | L13: 33381 | M13: 14446.715 | N13: 106752 | O13: 34984.546 | P13: 3.475
A14: 7 | B14: 7 | C14: 250513_gamme7 | E14: 12.16 | F14: Standard | G14: 4000 | H14: -5.6 | I14: bb | J14: 3776.474 | K14: 1231391 | L14: 46878 | M14: 34148.747 | N14: 348038 | O14: 33692.947 | P14: 3.538
A15: 26 | B15: 26 | C15: 250513_gamme2fin | E15: 12.16 | F15: Standard | G15: 110 | H15: 3.2 | I15: bb | J15: 113.5442 | K15: 20579 | L15: 23531 | M15: 1136.895 | N15: 5990 | O15: 3958.895 | P15: 3.435
A16: 27 | B16: 27 | C16: 250513_gamme4fin | E16: 12.15 | F16: Standard | G16: 540 | H16: 14 | I16: bb | J16: 615.3867 | K16: 104237 | L16: 26029 | M16: 5206.04 | N16: 30429 | O16: 16404.636 | P16: 3.426
A17: 28 | B17: 28 | C17: 250513_gamme5fin | E17: 12.15 | F17: Standard | G17: 1000 | H17: 26.7 | I17: bb | J17: 1267.1928 | K17: 184985 | L17: 22462 | M17: 10706.195 | N17: 53556 | O17: 10769.268 | P17: 3.454
A18: 29 | B18: 29 | C18: 250513_gamme7fin | E18: 12.16 | F18: Standard | G18: 4000 | H18: 7.9 | I18: bb | J18: 4315.0619 | K18: 810981 | L18: 26590 | M18: 39649.865 | N18: 236615 | O18: 61756.888 | P18: 3.427
A19: 8 | B19: 8 | C19: 250513_meoh1 | E19: 12.16 | I19: bb | K19: 589 | N19: 167 | O19: 38.033 | P19: 3.515
A20: 9 | B20: 9 | C20: 250513_blanc2 | E20: 12.16 | I20: bb | K20: 198 | N20: 46 | O20: 12.592 | P20: 4.266
A21: 10 | B21: 10 | C21: 250513_blanc3
A22: 11 | B22: 11 | C22: 250513_blanc4_d | L22: 36706 | R22: prise d'essai (g) | S22: quantité extrait (ng) | T22: µg/kg | U22: RDT SI %
A23: 12 | B23: 12 | C23: 250513_epx_J0_1 | E23: 12.16 | I23: bbI | K23: 135 | L23: 3434 | M23: 3.943 | N23: 34 | O23: 7.421 | P23: 4.023 | R23: 4.8419 | S23: =(J23*200*20/1000)*9/8 -> 0 | T23: =(S23*1000/R23)/1000 -> 0 | U23: =100+H56 -> 153
A24: 13 | B24: 13 | C24: 250513_epx_J0_2 | E24: 12.16 | I24: bbI | K24: 185 | L24: 3370 | M24: 5.485 | N24: 74 | O24: 72.497 | P24: 2.486 | R24: 4.8069 | S24: =(J24*200*20/1000)*9/8 -> 0 | T24: =(S24*1000/R24)/1000 -> 0 | U24: =100+H57 -> 150.1
A25: 14 | B25: 14 | C25: 250513_epx_J7_1 | E25: 12.16 | I25: MMI | K25: 62 | L25: 3145 | M25: 1.976 | O25: 24.755 | R25: 5.0617 | S25: =(J25*200*20/1000)*9/8 -> 0 | T25: =(S25*1000/R25)/1000 -> 0 | U25: =100+H58 -> 140.1
A26: 15 | B26: 15 | C26: 250513_epx_J14_3 | E26: 12.16 | I26: MMI | K26: 74 | L26: 2838 | M26: 2.596 | O26: 18.458 | R26: 4.8476 | S26: =(J26*200*20/1000)*9/8 -> 0 | T26: =(S26*1000/R26)/1000 -> 0 | U26: =100+H59 -> 126.4
A27: 16 | B27: 16 | C27: 250513_epx_J21_1 | E27: 12.16 | I27: MMI | K27: 93 | L27: 2828 | M27: 3.298 | O27: 11.263 | R27: 5.1044 | S27: =(J27*200*20/1000)*9/8 -> 0 | T27: =(S27*1000/R27)/1000 -> 0 | U27: =100+H60 -> 126
A28: 17 | B28: 17 | C28: 250513_imd_J0_1 | E28: 12.16 | I28: MMI | K28: 68 | L28: 2567 | M28: 2.632 | O28: 5.446 | R28: 4.906 | S28: =(J28*200*20/1000)*9/8 -> 0 | T28: =(S28*1000/R28)/1000 -> 0 | U28: =100+H61 -> 114.4
A29: 18 | B29: 18 | C29: 250513_imd_J0_2 | E29: 12.16 | I29: bbI | K29: 106 | L29: 2319 | M29: 4.561 | O29: 11.3 | R29: 4.9728 | S29: =(J29*200*20/1000)*9/8 -> 0 | T29: =(S29*1000/R29)/1000 -> 0 | U29: =100+H62 -> 103.3
A30: 19 | B30: 19 | C30: 250513_imd_J7_1 | E30: 12.16 | I30: MMI | K30: 51 | L30: 2232 | M30: 2.3 | O30: 4.754 | R30: 4.9158 | S30: =(J30*200*20/1000)*9/8 -> 0 | T30: =(S30*1000/R30)/1000 -> 0 | U30: =100+H63 -> 99.4
A31: 20 | B31: 20 | C31: 250513_imd_J14_3 | E31: 12.16 | I31: MMI | K31: 59 | L31: 2052 | M31: 2.869 | O31: 22.648 | R31: 5.1893 | S31: =(J31*200*20/1000)*9/8 -> 0 | T31: =(S31*1000/R31)/1000 -> 0 | U31: =100+H64 -> 91.4
A32: 21 | B32: 21 | C32: 250513_imd_J21_1 | E32: 12.16 | I32: MMI | K32: 77 | L32: 2254 | M32: 3.426 | O32: 10.099 | R32: 4.9038 | S32: =(J32*200*20/1000)*9/8 -> 0 | T32: =(S32*1000/R32)/1000 -> 0 | U32: =100+H65 -> 100.4
A33: 22 | B33: 22 | C33: 250513_meoh2
A34: 23 | B34: 23 | C34: 250513_blanc5
A35: 24 | B35: 24 | C35: 250513_blanc6
A36: 25 | B36: 25 | C36: 250513_blanc7d | L36: 24253
A38: Compound 2: Diflufenican-d3
B40: # | C40: Name | D40: Sample Text | E40: RT | F40: Type | G40: Std, Conc | H40: %Dev | I40: Primary Flags | J40: ng/l | K40: Area | L40: IS Area | M40: Response | N40: 1ｺ Area | O40: S/N | P40: 1ｺ Ratio (Actual)
A41: 1 | B41: 1 | C41: 250513_gamme1_4 | E41: 12.18 | F41: Standard | G41: 1300 | H41: -24.6 | I41: bb | J41: 980.4237 | K41: 22007 | M41: 22007.471 | O41: 4900.652
A42: 2 | B42: 2 | C42: 250513_gamme2 | E42: 12.18 | F42: Standard | G42: 1300 | H42: -17.8 | I42: bb | J42: 1069.034 | K42: 23996 | M42: 23996.496 | O42: 2118.949
A43: 3 | B43: 3 | C43: 250513_gamme3 | E43: 12.17 | F43: Standard | G43: 1300 | H43: 1.7 | I43: bb | J43: 1321.7146 | K43: 29668 | M43: 29668.393 | O43: 4322.856
A44: 4 | B44: 4 | C44: 250513_gamme4 | E44: 12.17 | F44: Standard | G44: 1300 | H44: 18.1 | I44: bb | J44: 1535.1859 | K44: 34460 | M44: 34460.16 | O44: 3411.255
A45: 5 | B45: 5 | C45: 250513_gamme5 | E45: 12.17 | F45: Standard | G45: 1300 | H45: 9.6 | I45: bb | J45: 1425.0609 | K45: 31988 | M45: 31988.197 | O45: 3627.192
...

Sheet résultats
F1: Résultats mg/kg de sol sec
D2: analyse n°1 | E2: analyse n°2 | F2: réplicat analytique, r = 2
A3: Epoxiconazole | D3: mg/kg de sol sec | E3: mg/kg de sol sec | F3: moyenne | G3: ecart-type
B4: 0 | C4: J0-1 | D4: ='250505_these Lisa_sol_cinetique'!T99 -> 0.7862445 | E4: ='250513_these Lisa_sol_cinetique'!T89 -> 0.7741224 | F4: =AVERAGE(D4:E4) -> 0.78018345 | G4: =STDEV(D4:E4) -> 0.0085716189
B5: 0 | C5: J0-2 | D5: ='250505_these Lisa_sol_cinetique'!T100 -> 1.103139 | E5: ='250513_these Lisa_sol_cinetique'!T90 -> 1.0371943 | F5: =AVERAGE(D5:E5) -> 1.0701667 | G5: =STDEV(D5:E5) -> 0.046629912
B6: 7 | C6: J7-1 | D6: ='250505_these Lisa_sol_cinetique'!T98 -> 0.70956495 | E6: ='250513_these Lisa_sol_cinetique'!T91 -> 0.73937088 | F6: =AVERAGE(D6:E6) -> 0.72446792 | G6: =STDEV(D6:E6) -> 0.021075978
B7: 14 | C7: J14-3 | D7: ='250505_these Lisa_sol_cinetique'!T101 -> 2.8317843 | E7: ='250513_these Lisa_sol_cinetique'!T92 -> 0.79043814 | F7: =E7 -> 0.79043814 | H7: *valeur exclue
B8: 21 | C8: J21-1 | D8: ='250505_these Lisa_sol_cinetique'!T96 -> 0.79721955 | E8: ='250513_these Lisa_sol_cinetique'!T93 -> 0.93527542 | F8: =AVERAGE(D8:E8) -> 0.86624748 | G8: =STDEV(D8:E8) -> 0.097620241
A10: Imdidacloprid | D10: mg/kg de sol sec | E10: mg/kg de sol sec
B11: 0 | C11: J0-1 | D11: ='250505_these Lisa_sol_cinetique'!T179 -> 0.085987935 | E11: ='250513_these Lisa_sol_cinetique'!T160 -> 0.092945271 | F11: =AVERAGE(D11:E11) -> 0.089466603 | G11: =STDEV(D11:E11) -> 0.0049195795
B12: 0 | C12: J0-2 | D12: ='250505_these Lisa_sol_cinetique'!T180 -> 0.068928075 | E12: ='250513_these Lisa_sol_cinetique'!T161 -> 0.07508642 | F12: =AVERAGE(D12:E12) -> 0.072007248 | G12: =STDEV(D12:E12) -> 0.0043546076
B13: 7 | C13: J7-1 | D13: ='250505_these Lisa_sol_cinetique'!T178 -> 0.080937405 | E13: ='250513_these Lisa_sol_cinetique'!T162 -> 0.082436836 | F13: =AVERAGE(D13:E13) -> 0.081687121 | G13: =STDEV(D13:E13) -> 0.0010602581
B14: 14 | C14: J14-3 | D14: ='250505_these Lisa_sol_cinetique'!T177 -> 0.080495775 | E14: ='250513_these Lisa_sol_cinetique'!T163 -> 0.086859808 | F14: =AVERAGE(D14:E14) -> 0.083677791 | G14: =STDEV(D14:E14) -> 0.0045000507
B15: 21 | C15: J21-1 | D15: ='250505_these Lisa_sol_cinetique'!T176 -> 0.06950403 | E15: ='250513_these Lisa_sol_cinetique'!T164 -> 0.076818427 | F15: =AVERAGE(D15:E15) -> 0.073161228 | G15: =STDEV(D15:E15) -> 0.0051720594
