Workbook

Sheet dose_epx_gamme basse
A1: Quantify Compound Summary Report
A3: Printed Fri Nov 28 09:50:15 2025
A5: Compound 1: Epoxiconazole
B7: Name | C7: Sample Text | D7: Type | E7: Std, Conc | F7: RT | G7: %Dev | H7: Conc, | I7: Area | J7: IS Area | K7: Response | L7: Detection Flags | M7: Sec,Area | N7: S/N | O7: Ion Ratio
A8: 1 | B8: 251126_gamme_A_1 | D8: Standard | E8: 0.264 | F8: 10.49 | G8: -3 | H8: 0.26 | I8: 7629 | K8: 7628.601 | L8: bb | M8: 2479.761 | N8: 725.13 | O8: 3.076
A9: 2 | B9: 251126_gamme_A_1bis | D9: Standard | E9: 0.264 | F9: 10.49 | G9: -0.8 | H9: 0.26 | I9: 7785 | K9: 7784.72 | L9: bb | M9: 2579.443 | N9: 994.734 | O9: 3.018
A10: 3 | B10: 251126_gamme_A_2 | D10: Standard | E10: 0.495 | F10: 10.49 | G10: -1.8 | H10: 0.49 | I10: 13933 | K10: 13932.592 | L10: bb | M10: 4509.233 | N10: 1159.841 | O10: 3.09
A11: 4 | B11: 251126_gamme_A_2bis | D11: Standard | E11: 0.495 | F11: 10.49 | G11: -1.5 | H11: 0.49 | I11: 13970 | K11: 13970.325 | L11: bb | M11: 4517.808 | N11: 509.053 | O11: 3.092
A12: 5 | B12: 251126_gamme_A_3 | D12: Standard | E12: 0.99 | F12: 10.49 | G12: 3.2 | H12: 1.02 | I12: 28552 | K12: 28552.418 | L12: bb | M12: 8808.975 | N12: 1481.192 | O12: 3.241
A13: 6 | B13: 251126_gamme_A_4 | D13: Standard | E13: 2.3 | F13: 10.49 | G13: -1 | H13: 2.28 | I13: 62639 | K13: 62638.641 | L13: bb | M13: 20564.629 | N13: 1909.979 | O13: 3.046
A14: 7 | B14: 251126_gamme_A_5 | D14: Standard | E14: 5.3 | F14: 10.49 | G14: -0.5 | H14: 5.27 | I14: 142551 | K14: 142550.67 | L14: bb | M14: 48973.914 | N14: 4522.603 | O14: 2.911
A15: 8 | B15: 251126_gamme_A_6 | D15: Standard | E15: 26.4 | F15: 10.49 | G15: -2.2 | H15: 25.83 | I15: 641877 | K15: 641877.19 | L15: bb | M15: 218719.55 | N15: 2371.604 | O15: 2.935
A16: 9 | B16: 251126_gamme_A_7 | D16: Standard | E16: 101.4 | F16: 10.49 | G16: -100 | I16: 2200098 | K16: 2200098.2 | L16: bbXI | M16: 775210 | N16: 4879.04 | O16: 2.838
A17: 10 | B17: 251126_gamme_A_8 | D17: Standard | E17: 253.5 | F17: 10.49 | G17: -100 | I17: 4700424 | K17: 4700423.5 | L17: bbXI | M17: 1589750.5 | N17: 4132.087 | O17: 2.957
A18: 49 | B18: 251126_gamme_B_2 | D18: Standard | E18: 0.495 | F18: 10.49 | G18: 3 | H18: 0.51 | I18: 14577 | K18: 14577.466 | L18: bb | M18: 4992.738 | N18: 1601.074 | O18: 2.92
A19: 50 | B19: 251126_gamme_B_4 | D19: Standard | E19: 2.3 | F19: 10.49 | G19: 1.1 | H19: 2.33 | I19: 63923 | K19: 63923.129 | L19: bb | M19: 21446.842 | N19: 2908.313 | O19: 2.98
A20: 51 | B20: 251126_gamme_B_6 | D20: Standard | E20: 26.4 | F20: 10.49 | G20: 2.2 | H20: 26.98 | I20: 667383 | K20: 667383.44 | L20: bb | M20: 221075.39 | N20: 6564 | O20: 3.019
A21: 52 | B21: 251126_gamme_B_8 | D21: Standard | E21: 253.5 | F21: 10.49 | G21: -100 | I21: 4655511 | K21: 4655510.5 | L21: bbXI | M21: 1562686.8 | N21: 3194.767 | O21: 2.979
A22: 56 | B22: 251126_gamme_B_0 | D22: Standard | E22: 0.041 | F22: 10.49 | G22: 1.2 | H22: 0.04 | I22: 1738 | K22: 1738.365 | L22: bb | M22: 553.977 | N22: 228.436 | O22: 3.138
A23: 11 | B23: 251126_blanc_MeOH_1 | F23: 10.49 | H23: 0.24 | I23: 7307 | K23: 7307.17 | L23: bb | M23: 2567.313 | N23: 419.902 | O23: 2.846
A24: 12 | B24: 251126_blanc_MeOH_2 | F24: 10.5 | H24: 0.04 | I24: 1749 | K24: 1749.175 | L24: bb | M24: 603.825 | N24: 197.743 | O24: 2.897
A25: 13 | B25: 251126_blanc_MeOH_3 | F25: 10.49 | H25: 0.01 | I25: 881 | K25: 880.801 | L25: bb | M25: 280.181 | N25: 106.161 | O25: 3.144
A26: 14 | B26: 251126_blanc_eau2 | F26: 10.5 | H26: 0 | I26: 606 | K26: 606.438 | L26: bb | M26: 137.602 | N26: 75.787 | O26: 4.407
A27: 15 | B27: 251126_blanc_eau3 | F27: 10.5 | I27: 234 | K27: 234.21 | L27: bbI | M27: 73.863 | N27: 29.845 | O27: 3.171
A28: 16 | B28: 251126_blanc_eau4 | F28: 10.49 | I28: 118 | K28: 117.8 | L28: bbI | M28: 32.742 | N28: 16.971 | O28: 3.598 | Q28: dilution | R28: prise d'essai en g | S28: quantité extraite µg | T28: ng/g | U28: quantité théorique µg | V28: RDT %
A29: 17 | B29: 251126_blanc_manip_1 | F29: 10.49 | I29: 193 | K29: 193.384 | L29: bbI | M29: 54.275 | N29: 52.991 | O29: 3.563
A30: 18 | B30: 251126_blanc_manip_2 | F30: 10.5 | I30: 187 | K30: 187.06 | L30: bbI | M30: 52.484 | N30: 48.675 | O30: 3.564
A31: 19 | B31: 251126_temoin_N0_D_1 | F31: 10.49 | H31: 0.05 | I31: 2053 | K31: 2053.354 | L31: bb | M31: 672.47 | N31: 299.761 | O31: 3.053 | Q31: 1 | R31: 5.0263 | S31: =(H31*Q31*1.2/1000)*(7/0.4) -> 0.00105 | T31: =S31*1000/R31 -> 0.20890118
A32: 20 | B32: 251126_temoin_N0_D_2 | F32: 10.49 | H32: 0.04 | I32: 1668 | K32: 1667.798 | L32: bb | M32: 658.144 | N32: 190.416 | O32: 2.534 | Q32: 1 | R32: 4.96 | S32: =(H32*Q32*1.2/1000)*(7/0.4) -> 0.00084 | T32: =S32*1000/R32 -> 0.16935484
A33: 21 | B33: 251126_dose_epx_i2_1 | F33: 10.49 | I33: 281 | K33: 281.47 | L33: bbI | M33: 101.91 | N33: 112.632 | O33: 2.762 | Q33: 20 | R33: 4.95
A34: 22 | B34: 251126_dose_epx_i2_2 | F34: 10.49 | H34: 0.01 | I34: 848 | K34: 847.989 | L34: bb | M34: 259.089 | N34: 137.66 | O34: 3.273 | Q34: 20 | R34: 4.966 | S34: =(H34*Q34*1.2/1000)*(7/0.1) -> 0.0168 | T34: =S34*1000/R34 -> 3.3830044
A35: 23 | B35: 251126_dose_epx_i5_1 | F35: 10.49 | I35: 263 | K35: 263.473 | L35: bbI | M35: 72.831 | N35: 78.242 | O35: 3.618 | Q35: 20 | R35: 4.9334
A36: 24 | B36: 251126_dose_epx_i5_2 | F36: 10.49 | I36: 115 | K36: 115.221 | L36: bbI | M36: 34.036 | N36: 33.291 | O36: 3.385 | Q36: 20 | R36: 4.9354
A37: 25 | B37: 251126_dose_epx_NOD_S5_1 | C37: dopé epx | F37: 10.49 | H37: 5.73 | I37: 154756 | K37: 154756.39 | L37: bb | M37: 52014.07 | N37: 2885.368 | O37: 2.975 | Q37: 60 | R37: 5.031 | S37: =(H37*Q37*1.2/1000)*(7/0.1) -> 28.8792 | T37: =S37*1000/R37 -> 5740.2504 | U37: =0.05*569.25 -> 28.4625 | V37: =(S37-S31)*100/U37 -> 101.46034 | W37: pas de correction de rendement
A38: 26 | B38: 251126_dose_epx_NOD_S5_2 | C38: dopé epx | F38: 10.49 | H38: 5.68 | I38: 153430 | K38: 153430.11 | L38: bb | M38: 51536.621 | N38: 3702.853 | O38: 2.977 | Q38: 60 | R38: 5.031 | S38: =(H38*Q38*1.2/1000)*(7/0.1) -> 28.6272 | T38: =S38*1000/R38 -> 5690.161 | U38: =0.05*569.25 -> 28.4625 | V38: =(S38-S32)*100/U38 -> 100.5757
A39: 27 | B39: 251126_dose_epx_h2_1 | F39: 10.49 | H39: 4.21 | I39: 114364 | K39: 114364.46 | L39: bb | M39: 38221.738 | N39: 1387.002 | O39: 2.992 | Q39: 20 | R39: 4.987 | S39: =(H39*Q39*1.2/1000)*(7/0.1) -> 7.0728 | T39: =S39*1000/R39 -> 1418.2474
A40: 28 | B40: 251126_dose_epx_h2_2 | F40: 10.49 | H40: 6.41 | I40: 172579 | K40: 172578.91 | L40: bb | M40: 56210.773 | N40: 4344.638 | O40: 3.07 | Q40: 20 | R40: 4.954 | S40: =(H40*Q40*1.2/1000)*(7/0.1) -> 10.7688 | T40: =S40*1000/R40 -> 2173.7586
A41: 29 | B41: 251126_dose_epx_g2_1 | F41: 10.49 | H41: 10.52 | I41: 278220 | K41: 278219.88 | L41: bb | M41: 94621.672 | N41: 4658.316 | O41: 2.94 | Q41: 20 | R41: 5.0216 | S41: =(H41*Q41*1.2/1000)*(7/0.1) -> 17.6736 | T41: =S41*1000/R41 -> 3519.5157
A42: 30 | B42: 251126_dose_epx_g2_2 | F42: 10.49 | H42: 11.15 | I42: 294210 | K42: 294210.44 | L42: bb | M42: 99288.539 | N42: 4929.533 | O42: 2.963 | Q42: 20 | R42: 5.0906 | S42: =(H42*Q42*1.2/1000)*(7/0.1) -> 18.732 | T42: =S42*1000/R42 -> 3679.7234
A43: 31 | B43: 251126_dose_epx_NOD_S2_1 | C43: dopé epx | F43: 10.49 | H43: 17.87 | I43: 458944 | K43: 458943.91 | L43: bb | M43: 153531.95 | N43: 4813.803 | O43: 2.989 | Q43: 20 | R43: 5.031 | S43: =(H43*Q43*1.2/1000)*(7/0.1) -> 30.0216 | T43: =S43*1000/R43 -> 5967.3226 | U43: =0.05*569.25 -> 28.4625 | V43: =(S43-S31)*100/U43 -> 105.47404 | W43: pas de correction de rendement
...

Sheet dose_epx_gamme haute
A1: Quantify Compound Summary Report
A3: Printed Fri Nov 28 09:54:58 2025
A5: Compound 1: Epoxiconazole
B7: Name | C7: Sample Text | D7: Type | E7: Std, Conc | F7: RT | G7: %Dev | H7: Conc, | I7: Area | J7: IS Area | K7: Response | L7: Detection Flags | M7: Sec,Area | N7: S/N | O7: Ion Ratio
A8: 1 | B8: 251126_gamme_A_1 | D8: Standard | E8: 0.264 | F8: 10.49 | G8: -100 | I8: 7629 | K8: 7628.601 | L8: bbXI | M8: 2479.761 | N8: 725.13 | O8: 3.076
A9: 2 | B9: 251126_gamme_A_1bis | D9: Standard | E9: 0.264 | F9: 10.49 | G9: -100 | I9: 7785 | K9: 7784.72 | L9: bbXI | M9: 2579.443 | N9: 994.734 | O9: 3.018
A10: 3 | B10: 251126_gamme_A_2 | D10: Standard | E10: 0.495 | F10: 10.49 | G10: -57.9 | H10: 0.21 | I10: 13933 | K10: 13932.592 | L10: bbX | M10: 4509.233 | N10: 1159.841 | O10: 3.09
A11: 4 | B11: 251126_gamme_A_2bis | D11: Standard | E11: 0.495 | F11: 10.49 | G11: -57.6 | H11: 0.21 | I11: 13970 | K11: 13970.325 | L11: bbX | M11: 4517.808 | N11: 509.053 | O11: 3.092
A12: 5 | B12: 251126_gamme_A_3 | D12: Standard | E12: 0.99 | F12: 10.49 | G12: -18.7 | H12: 0.8 | I12: 28552 | K12: 28552.418 | L12: bbX | M12: 8808.975 | N12: 1481.192 | O12: 3.241
A13: 6 | B13: 251126_gamme_A_4 | D13: Standard | E13: 2.3 | F13: 10.49 | G13: -4.4 | H13: 2.2 | I13: 62639 | K13: 62638.641 | L13: bb | M13: 20564.629 | N13: 1909.979 | O13: 3.046
A14: 7 | B14: 251126_gamme_A_5 | D14: Standard | E14: 5.3 | F14: 10.49 | G14: 3.4 | H14: 5.48 | I14: 142551 | K14: 142550.67 | L14: bb | M14: 48973.914 | N14: 4522.603 | O14: 2.911
A15: 8 | B15: 251126_gamme_A_6 | D15: Standard | E15: 26.4 | F15: 10.49 | G15: 0.4 | H15: 26.51 | I15: 641877 | K15: 641877.19 | L15: bb | M15: 218719.55 | N15: 2371.604 | O15: 2.935
A16: 9 | B16: 251126_gamme_A_7 | D16: Standard | E16: 101.4 | F16: 10.49 | G16: -2.3 | H16: 99.03 | I16: 2200098 | K16: 2200098.2 | L16: bb | M16: 775210 | N16: 4879.04 | O16: 2.838
A17: 10 | B17: 251126_gamme_A_8 | D17: Standard | E17: 253.5 | F17: 10.49 | G17: 1 | H17: 255.97 | I17: 4700424 | K17: 4700423.5 | L17: bb | M17: 1589750.5 | N17: 4132.087 | O17: 2.957
A18: 49 | B18: 251126_gamme_B_2 | D18: Standard | E18: 0.495 | F18: 10.49 | G18: -52.6 | H18: 0.23 | I18: 14577 | K18: 14577.466 | L18: bbX | M18: 4992.738 | N18: 1601.074 | O18: 2.92
A19: 50 | B19: 251126_gamme_B_4 | D19: Standard | E19: 2.3 | F19: 10.49 | G19: -2.1 | H19: 2.25 | I19: 63923 | K19: 63923.129 | L19: bb | M19: 21446.842 | N19: 2908.313 | O19: 2.98
A20: 51 | B20: 251126_gamme_B_6 | D20: Standard | E20: 26.4 | F20: 10.49 | G20: 4.6 | H20: 27.6 | I20: 667383 | K20: 667383.44 | L20: bb | M20: 221075.39 | N20: 6564 | O20: 3.019
A21: 52 | B21: 251126_gamme_B_8 | D21: Standard | E21: 253.5 | F21: 10.49 | G21: -0.5 | H21: 252.3 | I21: 4655511 | K21: 4655510.5 | L21: bb | M21: 1562686.8 | N21: 3194.767 | O21: 2.979
A22: 56 | B22: 251126_gamme_B_0 | D22: Standard | E22: 0.041 | F22: 10.49 | G22: -100 | I22: 1738 | K22: 1738.365 | L22: bbXI | M22: 553.977 | N22: 228.436 | O22: 3.138
A23: 11 | B23: 251126_blanc_MeOH_1 | F23: 10.49 | I23: 7307 | K23: 7307.17 | L23: bbI | M23: 2567.313 | N23: 419.902 | O23: 2.846
A24: 12 | B24: 251126_blanc_MeOH_2 | F24: 10.5 | I24: 1749 | K24: 1749.175 | L24: bbI | M24: 603.825 | N24: 197.743 | O24: 2.897
A25: 13 | B25: 251126_blanc_MeOH_3 | F25: 10.49 | I25: 881 | K25: 880.801 | L25: bbI | M25: 280.181 | N25: 106.161 | O25: 3.144
A26: 14 | B26: 251126_blanc_eau2 | F26: 10.5 | I26: 606 | K26: 606.438 | L26: bbI | M26: 137.602 | N26: 75.787 | O26: 4.407
A27: 15 | B27: 251126_blanc_eau3 | F27: 10.5 | I27: 234 | K27: 234.21 | L27: bbI | M27: 73.863 | N27: 29.845 | O27: 3.171
A28: 16 | B28: 251126_blanc_eau4 | F28: 10.49 | I28: 118 | K28: 117.8 | L28: bbI | M28: 32.742 | N28: 16.971 | O28: 3.598 | Q28: dilution | R28: prise d'essai en g | S28: quantité extraite µg | T28: ng/g | U28: quantité théorique µg | V28: RDT %
A29: 17 | B29: 251126_blanc_manip_1 | F29: 10.49 | I29: 193 | K29: 193.384 | L29: bbI | M29: 54.275 | N29: 52.991 | O29: 3.563
A30: 18 | B30: 251126_blanc_manip_2 | F30: 10.5 | I30: 187 | K30: 187.06 | L30: bbI | M30: 52.484 | N30: 48.675 | O30: 3.564
A31: 19 | B31: 251126_temoin_N0_D_1 | F31: 10.49 | I31: 2053 | K31: 2053.354 | L31: bbI | M31: 672.47 | N31: 299.761 | O31: 3.053 | Q31: 1 | R31: 5.0263
A32: 20 | B32: 251126_temoin_N0_D_2 | F32: 10.49 | I32: 1668 | K32: 1667.798 | L32: bbI | M32: 658.144 | N32: 190.416 | O32: 2.534 | Q32: 1 | R32: 4.96
A33: 21 | B33: 251126_dose_epx_i2_1 | F33: 10.49 | I33: 281 | K33: 281.47 | L33: bbI | M33: 101.91 | N33: 112.632 | O33: 2.762 | Q33: 20 | R33: 4.95
A34: 22 | B34: 251126_dose_epx_i2_2 | F34: 10.49 | I34: 848 | K34: 847.989 | L34: bbI | M34: 259.089 | N34: 137.66 | O34: 3.273 | Q34: 20 | R34: 4.966
A35: 23 | B35: 251126_dose_epx_i5_1 | F35: 10.49 | I35: 263 | K35: 263.473 | L35: bbI | M35: 72.831 | N35: 78.242 | O35: 3.618 | Q35: 20 | R35: 4.9334
A36: 24 | B36: 251126_dose_epx_i5_2 | F36: 10.49 | I36: 115 | K36: 115.221 | L36: bbI | M36: 34.036 | N36: 33.291 | O36: 3.385 | Q36: 20 | R36: 4.9354
A37: 25 | B37: 251126_dose_epx_NOD_S5_1 | C37: dopé epx | F37: 10.49 | H37: 5.99 | I37: 154756 | K37: 154756.39 | L37: bb | M37: 52014.07 | N37: 2885.368 | O37: 2.975 | Q37: 60 | R37: 5.031 | S37: =(H37*Q37*1.2/1000)*(7/0.1) -> 30.1896 | T37: =S37*1000/R37 -> 6000.7156 | U37: =0.05*569.25 -> 28.4625 | V37: =(S37-S31)*100/U37 -> 106.06798 | W37: pas de correction de rendement
A38: 26 | B38: 251126_dose_epx_NOD_S5_2 | C38: dopé epx | F38: 10.49 | H38: 5.93 | I38: 153430 | K38: 153430.11 | L38: bb | M38: 51536.621 | N38: 3702.853 | O38: 2.977 | Q38: 60 | R38: 5.031 | S38: =(H38*Q38*1.2/1000)*(7/0.1) -> 29.8872 | T38: =S38*1000/R38 -> 5940.6082 | U38: =0.05*569.25 -> 28.4625 | V38: =(S38-S32)*100/U38 -> 105.00553
A39: 27 | B39: 251126_dose_epx_h2_1 | F39: 10.49 | H39: 4.32 | I39: 114364 | K39: 114364.46 | L39: bb | M39: 38221.738 | N39: 1387.002 | O39: 2.992 | Q39: 20 | R39: 4.987 | S39: =(H39*Q39*1.2/1000)*(7/0.1) -> 7.2576 | T39: =S39*1000/R39 -> 1455.3038
A40: 28 | B40: 251126_dose_epx_h2_2 | F40: 10.49 | H40: 6.72 | I40: 172579 | K40: 172578.91 | L40: bb | M40: 56210.773 | N40: 4344.638 | O40: 3.07 | Q40: 20 | R40: 4.954 | S40: =(H40*Q40*1.2/1000)*(7/0.1) -> 11.2896 | T40: =S40*1000/R40 -> 2278.8857
A41: 29 | B41: 251126_dose_epx_g2_1 | F41: 10.49 | H41: 11.11 | I41: 278220 | K41: 278219.88 | L41: bb | M41: 94621.672 | N41: 4658.316 | O41: 2.94 | Q41: 20 | R41: 5.0216 | S41: =(H41*Q41*1.2/1000)*(7/0.1) -> 18.6648 | T41: =S41*1000/R41 -> 3716.903
A42: 30 | B42: 251126_dose_epx_g2_2 | F42: 10.49 | H42: 11.77 | I42: 294210 | K42: 294210.44 | L42: bb | M42: 99288.539 | N42: 4929.533 | O42: 2.963 | Q42: 20 | R42: 5.0906 | S42: =(H42*Q42*1.2/1000)*(7/0.1) -> 19.7736 | T42: =S42*1000/R42 -> 3884.3358
A43: 31 | B43: 251126_dose_epx_NOD_S2_1 | C43: dopé epx | F43: 10.49 | H43: 18.7 | I43: 458944 | K43: 458943.91 | L43: bb | M43: 153531.95 | N43: 4813.803 | O43: 2.989 | Q43: 20 | R43: 5.031 | S43: =(H43*Q43*1.2/1000)*(7/0.1) -> 31.416 | T43: =S43*1000/R43 -> 6244.4842 | U43: =0.05*569.25 -> 28.4625 | V43: =(S43-S31)*100/U43 -> 110.37681 | W43: pas de correction de rendement
...

Sheet dose_imd
A1: Compound 2: Imidacloprid
B3: Name | C3: Sample Text | D3: Type | E3: Std, Conc | F3: RT | G3: %Dev | H3: Conc, | I3: Area | J3: IS Area | K3: Response | L3: Detection Flags | M3: Sec,Area | N3: S/N | O3: Ion Ratio
A4: 1 | B4: 251126_gamme_B_2 | D4: Standard | E4: 0.499 | F4: 6.23 | G4: 1.6 | H4: 0.51 | I4: 1565 | K4: 1565.101 | L4: bb | M4: 1453.736 | N4: 185.23 | O4: 1.077
A5: 2 | B5: 251126_gamme_B_4 | D5: Standard | E5: 2.3 | F5: 6.23 | G5: 26.7 | H5: 2.91 | I5: 6587 | K5: 6587.181 | L5: bb | M5: 6094.855 | N5: 1014.385 | O5: 1.081
A6: 3 | B6: 251126_gamme_B_6 | D6: Standard | E6: 26.6 | F6: 6.23 | G6: 3.2 | H6: 27.44 | I6: 54706 | K6: 54706.016 | L6: bb | M6: 51796.805 | N6: 3246.873 | O6: 1.056
A7: 4 | B7: 251126_gamme_B_8 | D7: Standard | E7: 255.7 | F7: 6.23 | G7: -100 | I7: 343652 | K7: 343652 | L7: bbXI | M7: 332459.22 | N7: 9067.773 | O7: 1.034
A8: 8 | B8: 251126_gamme_B_0 | D8: Standard | E8: 0.042 | F8: 6.23 | G8: -100 | I8: 290 | K8: 289.851 | L8: bbXI | M8: 273.5 | N8: 29.14 | O8: 1.06
A9: 38 | B9: 251126_gamme_C_1 | D9: Standard | E9: 0.266 | F9: 6.23 | G9: -25.4 | H9: 0.2 | I9: 918 | K9: 917.703 | L9: bb | M9: 793.417 | N9: 47.481 | O9: 1.157
A10: 39 | B10: 251126_gamme_C_1bis | D10: Standard | E10: 0.266 | F10: 6.23 | G10: -31.8 | H10: 0.18 | I10: 882 | K10: 881.819 | L10: bb | M10: 834.94 | N10: 73.583 | O10: 1.056
A11: 40 | B11: 251126_gamme_C_2 | D11: Standard | E11: 0.499 | F11: 6.23 | G11: -9.4 | H11: 0.45 | I11: 1450 | K11: 1450.102 | L11: bb | M11: 1329.389 | N11: 170.409 | O11: 1.091
A12: 41 | B12: 251126_gamme_C_2bis | D12: Standard | E12: 0.499 | F12: 6.23 | G12: 4.8 | H12: 0.52 | I12: 1599 | K12: 1598.718 | L12: bb | M12: 1361.214 | N12: 180.224 | O12: 1.174
A13: 42 | B13: 251126_gamme_C_3 | D13: Standard | E13: 1 | F13: 6.23 | G13: 10.6 | H13: 1.11 | I13: 2820 | K13: 2820.496 | L13: bb | M13: 2582.276 | N13: 362.651 | O13: 1.092
A14: 43 | B14: 251126_gamme_C_4 | D14: Standard | E14: 2.3 | F14: 6.23 | G14: 16.4 | H14: 2.68 | I14: 6097 | K14: 6096.737 | L14: bb | M14: 5775.048 | N14: 702.153 | O14: 1.056
A15: 44 | B15: 251126_gamme_C_5 | D15: Standard | E15: 5.3 | F15: 6.23 | G15: 15.5 | H15: 6.12 | I15: 13193 | K15: 13193.373 | L15: bb | M15: 12204.813 | N15: 1225.13 | O15: 1.081
A16: 45 | B16: 251126_gamme_C_6 | D16: Standard | E16: 26.6 | F16: 6.23 | G16: -12.6 | H16: 23.26 | I16: 46894 | K16: 46893.738 | L16: bb | M16: 44241.91 | N16: 4923.019 | O16: 1.06
A17: 46 | B17: 251126_gamme_C_7 | D17: Standard | E17: 102.3 | F17: 6.23 | G17: 0.9 | H17: 103.25 | I17: 168055 | K17: 168054.69 | L17: bb | M17: 155194.44 | N17: 7573.237 | O17: 1.083
A18: 47 | B18: 251126_gamme_C_8 | D18: Standard | E18: 255.7 | F18: 6.23 | G18: -100 | I18: 345389 | K18: 345389.22 | L18: bbXI | M18: 327638.28 | N18: 966.582 | O18: 1.054
A19: 5 | B19: 251126_blanc_MeOH_6 | F19: 6.23 | I19: 448 | K19: 448.328 | L19: bbI | M19: 442.762 | N19: 43.836 | O19: 1.013
A20: 6 | B20: 251126_blanc_MeOH_7 | F20: 6.23 | I20: 200 | K20: 200.435 | L20: bbI | M20: 149.064 | N20: 28.552 | O20: 1.345
A21: 7 | B21: 251126_blanc_eau7
A22: 9 | B22: 251126_blanc_eau8 | Q22: prise d'essai en g | R22: quantité extraite µg | S22: ng/g | T22: ng/g corrigé du rdt | U22: quantité théorique µg | V22: RDT % | W22: moyenne rdt %
A23: 10 | B23: 251126_dose_imd_e2_1 | F23: 6.25 | H23: 0.12 | I23: 755 | K23: 754.973 | L23: bb | M23: 684.249 | N23: 99.835 | O23: 1.103 | Q23: 4.963 | R23: =(H23*1.2/1000)*(7/0.4) -> 0.00252 | S23: =R23*1000/Q23 -> 0.5077574 | T23: =S23*100/$W$35 -> 0.72041211
A24: 11 | B24: 251126_dose_imd_e2_2 | F24: 6.24 | I24: 121 | K24: 120.651 | L24: bbI | M24: 94.117 | N24: 13.862 | O24: 1.282 | Q24: 5.0391 | R24: =(H24*1.2/1000)*(7/0.4) -> 0
A25: 12 | B25: 251126_dose_imd_e5_1 | F25: 6.29 | I25: 106 | K25: 106.352 | L25: MMI | M25: 114.123 | N25: 9.658 | O25: 0.932 | Q25: 4.9804 | R25: =(H25*1.2/1000)*(7/0.4) -> 0
A26: 13 | B26: 251126_dose_imd_e5_2 | F26: 6.23 | I26: 82 | K26: 81.625 | L26: MMI | M26: 75.653 | N26: 16.097 | O26: 1.079 | Q26: 5.062 | R26: =(H26*1.2/1000)*(7/0.4) -> 0
A27: 14 | B27: 251126_dose_imd_f2_1 | F27: 6.23 | H27: 0.88 | I27: 2343 | K27: 2342.612 | L27: bb | M27: 2238.302 | N27: 208.634 | O27: 1.047 | Q27: 5.046 | R27: =(H27*1.2/1000)*(7/0.4) -> 0.01848 | S27: =R27*1000/Q27 -> 3.6623068 | T27: =S27*100/$W$35 -> 5.1961235
A28: 15 | B28: 251126_dose_imd_f2_2 | F28: 6.23 | H28: 0.93 | I28: 2461 | K28: 2461.21 | L28: bb | M28: 2204.562 | N28: 250.749 | O28: 1.116 | Q28: 5.0867 | R28: =(H28*1.2/1000)*(7/0.4) -> 0.01953 | S28: =R28*1000/Q28 -> 3.8394244 | T28: =S28*100/$W$35 -> 5.44742
A29: 16 | B29: 251126_dose_imd_g2_1 | F29: 6.23 | H29: 1.62 | I29: 3891 | K29: 3890.631 | L29: bb | M29: 3488 | N29: 285.003 | O29: 1.115 | Q29: 5.0216 | R29: =(H29*1.2/1000)*(7/0.4) -> 0.03402 | S29: =R29*1000/Q29 -> 6.7747332 | T29: =S29*100/$W$35 -> 9.6120702
A30: 17 | B30: 251126_dose_imd_g2_2 | F30: 6.23 | H30: 1.58 | I30: 3802 | K30: 3801.926 | L30: bb | M30: 3677.85 | N30: 456.964 | O30: 1.034 | Q30: 5.0906 | R30: =(H30*1.2/1000)*(7/0.4) -> 0.03318 | S30: =R30*1000/Q30 -> 6.5178957 | T30: =S30*100/$W$35 -> 9.2476663
A31: 18 | B31: 251126_dose_imd_h2_1 | F31: 6.24 | H31: 2.09 | I31: 4874 | K31: 4873.909 | L31: bb | M31: 4285.241 | N31: 407.3 | O31: 1.137 | Q31: 4.987 | R31: =(H31*1.2/1000)*(7/0.4) -> 0.04389 | S31: =R31*1000/Q31 -> 8.8008823 | T31: =S31*100/$W$35 -> 12.486794
A32: 19 | B32: 251126_dose_imd_h2_2 | F32: 6.24 | H32: 2.16 | I32: 5015 | K32: 5014.766 | L32: bb | M32: 4636.182 | N32: 633.431 | O32: 1.082 | Q32: 4.954 | R32: =(H32*1.2/1000)*(7/0.4) -> 0.04536 | S32: =R32*1000/Q32 -> 9.1562374 | T32: =S32*100/$W$35 -> 12.990976
A33: 20 | B33: 251126_dose_imd_i2_1 | F33: 6.23 | H33: 3.66 | I33: 8144 | K33: 8143.936 | L33: bb | M33: 7432.67 | N33: 186.438 | O33: 1.096 | Q33: 4.95 | R33: =(H33*1.2/1000)*(7/0.4) -> 0.07686 | S33: =R33*1000/Q33 -> 15.527273 | T33: =S33*100/$W$35 -> 22.030275
A34: 21 | B34: 251126_dose_imd_i2_2 | F34: 6.23 | H34: 3.62 | I34: 8055 | K34: 8055.396 | L34: bb | M34: 7400.826 | N34: 682.031 | O34: 1.088 | Q34: 4.9662 | R34: =(H34*1.2/1000)*(7/0.4) -> 0.07602 | S34: =R34*1000/Q34 -> 15.307479 | T34: =S34*100/$W$35 -> 21.718429
A35: 22 | B35: 251126_dose_imd_NOD_1 | C35: dopé imd | F35: 6.23 | H35: 16.18 | I35: 33314 | K35: 33313.684 | L35: bb | M35: 31556.709 | N35: 2311.574 | O35: 1.056 | Q35: 5.031 | R35: =(H35*1.2/1000)*(7/0.4) -> 0.33978 | S35: =R35*1000/Q35 -> 67.537269 | U35: =0.05*9.74 -> 0.487 | V35: =R35*100/U35 -> 69.770021 | W35: =AVERAGE(V35:V36) -> 70.48152
A36: 23 | B36: 251126_dose_imd_NOD_2 | C36: dopé imd | F36: 6.23 | H36: 16.51 | I36: 33953 | K36: 33952.934 | L36: bb | M36: 31665.307 | N36: 3594.676 | O36: 1.072 | Q36: 5.031 | R36: =(H36*1.2/1000)*(7/0.4) -> 0.34671 | S36: =R36*1000/Q36 -> 68.914729 | U36: =0.05*9.74 -> 0.487 | V36: =R36*100/U36 -> 71.193018
A37: 24 | B37: 251126_dose_imd_f5_1 | F37: 6.23 | H37: 16.44 | I37: 33813 | K37: 33813.418 | L37: bb | M37: 32083.521 | N37: 2795.832 | O37: 1.054 | Q37: 4.934 | R37: =(H37*1.2/1000)*(7/0.4) -> 0.34524 | S37: =R37*1000/Q37 -> 69.971625 | T37: =S37*100/$W$35 -> 99.276556
A38: 25 | B38: 251126_dose_imd_f5_2 | F38: 6.24 | H38: 16.98 | I38: 34874 | K38: 34874.117 | L38: bb | M38: 32166.307 | N38: 5272.305 | O38: 1.084 | Q38: 5.063 | R38: =(H38*1.2/1000)*(7/0.4) -> 0.35658 | S38: =R38*1000/Q38 -> 70.4286 | T38: =S38*100/$W$35 -> 99.924917
A39: 26 | B39: 251126_dose_imd_g5_1 | F39: 6.24 | H39: 27.74 | I39: 55249 | K39: 55249.02 | L39: bb | M39: 53529.059 | N39: 3973.466 | O39: 1.032 | Q39: 4.992 | R39: =(H39*1.2/1000)*(7/0.4) -> 0.58254 | S39: =R39*1000/Q39 -> 116.69471 | T39: =S39*100/$W$35 -> 165.56781
A40: 27 | B40: 251126_dose_imd_g5_2 | F40: 6.23 | H40: 24.84 | I40: 49862 | K40: 49862.215 | L40: bb | M40: 48318.457 | N40: 3017.864 | O40: 1.032 | Q40: 5.0566 | R40: =(H40*1.2/1000)*(7/0.4) -> 0.52164 | S40: =R40*1000/Q40 -> 103.16023 | T40: =S40*100/$W$35 -> 146.36493
A41: 28 | B41: 251126_dose_imd_h5_1 | F41: 6.24 | H41: 57.28 | I41: 105691 | K41: 105691.23 | L41: bb | M41: 98592.867 | N41: 7893.577 | O41: 1.072 | Q41: 5.0796 | R41: =(H41*1.2/1000)*(7/0.4) -> 1.20288 | S41: =R41*1000/Q41 -> 236.80605 | T41: =S41*100/$W$35 -> 335.98318
...

Sheet résultats
D1: IMD quantifié dans les sols ng/g | I1: EPX quantifié dans les sols ng/g
A2: ligne | B2: ratio | C2: dose nominale IMD ng/g | D2: rep 1 | E2: rep2 | F2: moyenne | H2: dose nominale EPX ng/g | I2: rep 1 | J2: rep2 | K2: moyenne
A3: sol témoin N0 | B3: D | D3: 0 | E3: 0 | F3: =AVERAGE(D3:E3) -> 0 | I3: ='dose_epx_gamme basse'!T31 -> 0.20890118 | J3: ='dose_epx_gamme basse'!T32 -> 0.16935484 | K3: =AVERAGE(I3:J3) -> 0.18912801
A4: 2 | B4: E | C4: 0 | D4: =dose_imd!T23 -> 0.72041211 | E4: 0 | F4: =AVERAGE(D4:E4) -> 0.36020606 | H4: 9418.1 | I4: ='dose_epx_gamme basse'!T47 -> 6797.1791 | J4: ='dose_epx_gamme basse'!T48 -> 7021.2538 | K4: =AVERAGE(I4:J4) -> 6909.2165 | L4: =K4/H4 -> 0.73361044
A5: 2 | B5: F | C5: 6.5 | D5: =dose_imd!T27 -> 5.1961235 | E5: =dose_imd!T28 -> 5.44742 | F5: =AVERAGE(D5:E5) -> 5.3217717 | H5: 7063.6 | I5: ='dose_epx_gamme basse'!T45 -> 5157.1938 | J5: ='dose_epx_gamme basse'!T46 -> 5181.9844 | K5: =AVERAGE(I5:J5) -> 5169.5891 | L5: =K5/H5 -> 0.73186323 | M5: =F5/C5 -> 0.81873411
A6: 2 | B6: G | C6: 13.1 | D6: =dose_imd!T29 -> 9.6120702 | E6: =dose_imd!T30 -> 9.2476663 | F6: =AVERAGE(D6:E6) -> 9.4298683 | H6: 4709 | I6: ='dose_epx_gamme basse'!T41 -> 3519.5157 | J6: ='dose_epx_gamme basse'!T42 -> 3679.7234 | K6: =AVERAGE(I6:J6) -> 3599.6196 | L6: =K6/H6 -> 0.76441273 | M6: =F6/C6 -> 0.71983727
A7: 2 | B7: H | C7: 19.6 | D7: =dose_imd!T31 -> 12.486794 | E7: =dose_imd!T32 -> 12.990976 | F7: =AVERAGE(D7:E7) -> 12.738885 | H7: 2354.5 | I7: ='dose_epx_gamme basse'!T39 -> 1418.2474 | J7: ='dose_epx_gamme basse'!T40 -> 2173.7586 | K7: =AVERAGE(I7:J7) -> 1796.003 | L7: =K7/H7 -> 0.76279593 | M7: =F7/C7 -> 0.64994312
A8: 2 | B8: I | C8: 26.1 | D8: =dose_imd!T33 -> 22.030275 | E8: =dose_imd!T34 -> 21.718429 | F8: =AVERAGE(D8:E8) -> 21.874352 | H8: 0 | I8: ='dose_epx_gamme basse'!T33 -> 0 | J8: ='dose_epx_gamme basse'!T34 -> 3.3830044 | K8: =AVERAGE(I8:J8) -> 1.6915022 | M8: =F8/C8 -> 0.83809778
A9: 5 | B9: E | C9: =C4*18 -> 0 | D9: 0 | E9: 0 | F9: =AVERAGE(D9:E9) -> 0 | H9: =H4*18 -> 169525.8 | I9: ='dose_epx_gamme haute'!T55 -> 127730.46 | J9: ='dose_epx_gamme haute'!T56 -> 125532.04 | K9: =AVERAGE(I9:J9) -> 126631.25 | L9: =K9/H9 -> 0.74697334
A10: 5 | B10: F | C10: =C5*18 -> 117 | D10: =dose_imd!T37 -> 99.276556 | E10: =dose_imd!T38 -> 99.924917 | F10: =AVERAGE(D10:E10) -> 99.600737 | H10: =H5*18 -> 127144.8 | I10: ='dose_epx_gamme haute'!T53 -> 92474.909 | J10: ='dose_epx_gamme haute'!T54 -> 112197.99 | K10: =AVERAGE(I10:J10) -> 102336.45 | L10: =K10/H10 -> 0.8048811 | M10: =F10/C10 -> 0.85128835
A11: 5 | B11: G | C11: =C6*18 -> 235.8 | D11: =dose_imd!T39 -> 165.56781 | E11: =dose_imd!T40 -> 146.36493 | F11: =AVERAGE(D11:E11) -> 155.96637 | H11: =H6*18 -> 84762 | I11: ='dose_epx_gamme haute'!T51 -> 64413.462 | J11: ='dose_epx_gamme haute'!T52 -> 67647.194 | K11: =AVERAGE(I11:J11) -> 66030.328 | L11: =K11/H11 -> 0.77900861 | M11: =F11/C11 -> 0.661435
A12: 5 | B12: H | C12: =C7*18 -> 352.8 | D12: =dose_imd!T41 -> 335.98318 | E12: =dose_imd!T42 -> 340.56661 | F12: =AVERAGE(D12:E12) -> 338.27489 | H12: =H7*18 -> 42381 | I12: ='dose_epx_gamme haute'!T49 -> 35850.282 | J12: ='dose_epx_gamme haute'!T50 -> 36135.849 | K12: =AVERAGE(I12:J12) -> 35993.066 | L12: =K12/H12 -> 0.84927363 | M12: =F12/C12 -> 0.95882906
A13: 5 | B13: I | C13: =C8*18 -> 469.8 | D13: =dose_imd!T43 -> 422.8222 | E13: =dose_imd!T44 -> 422.10753 | F13: =AVERAGE(D13:E13) -> 422.46487 | H13: =H8*18 -> 0 | I13: ='dose_epx_gamme basse'!T35 -> 0 | J13: ='dose_epx_gamme basse'!T36 -> 0 | K13: =AVERAGE(I13:J13) -> 0 | M13: =F13/C13 -> 0.89924407
L15: =AVERAGE(L4:L12) -> 0.77160238 | M15: =AVERAGE(M4:M13) -> 0.79967609
