Workbook

Sheet facteur récupération
A1: Données | B1: Valeur
A2: extraction 1
A3: V acn ajouté ml | B3: 5
A4: V acn récupéré ml | B4: 3
A5: % récupéré | B5: =B4*100/B3 -> 60
A6: extraction 2
A7: V acn restant de 1 | B7: =B3-B4 -> 2
A8: V acn ajouté ml | B8: 5
A9: V acn récupéré | B9: 3
A10: % récupéré | B10: =((B3-B4)/B3)*B9*100/(B8+B7) -> 17.142857
A11: V extrait (1+2) ml | B11: =B9+B4 -> 6
A12: % récupéré e1 + e2 | B12: =B5+B10 -> 77.142857
A13: facteur de correction pour 100 % | B13: =100/B12 -> 1.2962963

Sheet 260210_tese Lisa_vdt_TKbis
A1: Quantify Compound Summary Report
A3: Printed Wed Feb 11 14:03:40 2026
A5: Compound 1: epoxiconazole
B7: Name | C7: Sample Text | D7: RT | E7: Type | F7: Std, Conc | G7: %Dev | H7: Primary Flags | I7: ng/l | J7: Area | K7: IS Area | L7: Response | M7: 1ｺ Area | N7: S/N | O7: 1ｺ Ratio (Actual)
A8: 1 | B8: 260210_gamme_A_1 | D8: 10.19 | E8: Standard | F8: 4.05 | G8: -0.9 | H8: bb | I8: 4.014 | J8: 102350 | K8: 3165509 | L8: 5.87 | M8: 23534 | N8: 3108.5 | O8: 4.35
A9: 2 | B9: 260210_gamme_A_1bis | D9: 10.19 | E9: Standard | F9: 4.05 | G9: -0.7 | H9: bb | I9: 4.021 | J9: 100124 | K9: 3090725 | L9: 5.88 | M9: 23033 | N9: 2934.9 | O9: 4.35
A10: 3 | B10: 260210_gamme_A_2 | D10: 10.19 | E10: Standard | F10: 14.17 | G10: -6.2 | H10: bb | I10: 13.297 | J10: 346750 | K10: 3127273 | L10: 20.14 | M10: 73109 | N10: 6659 | O10: 4.74
A11: 4 | B11: 260210_gamme_A_2bis | D11: 10.19 | E11: Standard | F11: 14.17 | G11: -5.3 | H11: bb | I11: 13.413 | J11: 342950 | K11: 3065920 | L11: 20.32 | M11: 72428 | N11: 29573.9 | O11: 4.74
A12: 5 | B12: 260210_gamme_A_3 | D12: 10.19 | E12: Standard | F12: 80.96 | G12: -6 | H12: bb | I12: 76.103 | J12: 1945709 | K12: 3057340 | L12: 115.61 | M12: 394252 | N12: 106029.8 | O12: 4.94
A13: 6 | B13: 260210_gamme_A_4 | D13: 10.19 | E13: Standard | F13: 161.92 | G13: 2.3 | H13: bb | I13: 165.571 | J13: 3977777 | K13: 2909259 | L13: 248.38 | M13: 808082 | N13: 71977.8 | O13: 4.92
A14: 7 | B14: 260210_gamme_A_5 | D14: 10.19 | E14: Standard | F14: 404.8 | G14: -0.5 | H14: bb | I14: 402.64 | J14: 9664033 | K14: 3017027 | L14: 581.89 | M14: 1964989 | N14: 424902 | O14: 4.92
A15: 8 | B15: 260210_gamme_A_6 | D15: 10.2 | E15: Standard | F15: 1012 | G15: 2.5 | H15: bbX | I15: 1037.51 | J15: 22871402 | K15: 3091126 | L15: 1344.11 | M15: 4695053 | N15: 158188.9 | O15: 4.87
A16: 9 | B16: 260210_gamme_A_7 | D16: 10.2 | E16: Standard | F16: 3036 | H16: bbXIO | J16: 53880528 | K16: 2946528 | L16: 3321.85 | M16: 11496235 | N16: 2022101.9 | O16: 4.69
A17: 10 | B17: 260210_gamme_A_7bis | D17: 10.2 | E17: Standard | F17: 3036 | H17: bbXIO | J17: 53129568 | K17: 2865609 | L17: 3368.05 | M17: 11255809 | N17: 754153088 | O17: 4.72
A18: 11 | B18: 260210_gamme_A_8 | D18: 10.2 | E18: Standard | F18: 5060 | H18: bbXIO | J18: 75603280 | K18: 2740289 | L18: 5011.91 | M18: 16643956 | N18: 1041403712 | O18: 4.54
A19: 42 | B19: 260210_gamme_B_1 | D19: 10.19 | E19: Standard | F19: 4.05 | G19: 5 | H19: bb | I19: 4.254 | J19: 110340 | K19: 3210772 | L19: 6.24 | M19: 25319 | N19: 5858.8 | O19: 4.36
A20: 43 | B20: 260210_gamme_B_1bis | D20: 10.19 | E20: Standard | F20: 4.05 | G20: 4.2 | H20: bb | I20: 4.219 | J20: 108842 | K20: 3194451 | L20: 6.19 | M20: 24712 | N20: 2972.1 | O20: 4.4
A21: 44 | B21: 260210_gamme_B_2 | D21: 10.19 | E21: Standard | F21: 14.17 | G21: 2 | H21: bb | I21: 14.456 | J21: 375250 | K21: 3109684 | L21: 21.92 | M21: 77940 | N21: 17405.2 | O21: 4.81
A22: 45 | B22: 260210_gamme_B_2bis | D22: 10.19 | E22: Standard | F22: 14.17 | G22: 4.2 | H22: bb | I22: 14.761 | J22: 374016 | K22: 3034616 | L22: 22.39 | M22: 77657 | N22: 8713.6 | O22: 4.82
A23: 46 | B23: 260210_gamme_B_3 | D23: 10.2 | E23: Standard | F23: 80.96 | G23: -0.8 | H23: bb | I23: 80.3 | J23: 2094972 | K23: 3121440 | L23: 121.92 | M23: 422836 | N23: 84709.1 | O23: 4.95
A24: 47 | B24: 260210_gamme_B_4 | D24: 10.19 | E24: Standard | F24: 161.92 | G24: 2.9 | H24: bb | I24: 166.563 | J24: 4338262 | K24: 3154491 | L24: 249.83 | M24: 870006 | N24: 369307.7 | O24: 4.99
A25: 48 | B25: 260210_gamme_B_5 | D25: 10.19 | E25: Standard | F25: 404.8 | G25: 0 | H25: bb | I25: 404.619 | J25: 10393703 | K25: 3229993 | L25: 584.56 | M25: 2108664 | N25: 164674880 | O25: 4.93
A26: 49 | B26: 260210_gamme_B_6 | D26: 10.19 | E26: Standard | F26: 1012 | G26: 1.4 | H26: bbX | I26: 1026.049 | J26: 24072722 | K26: 3282971 | L26: 1332.04 | M26: 5008652 | N26: 366657888 | O26: 4.81
A27: 50 | B27: 260210_gamme_B_7 | D27: 10.19 | E27: Standard | F27: 3036 | H27: bbXIO | J27: 54838584 | K27: 2953165 | L27: 3373.32 | M27: 11897643 | N27: 765602752 | O27: 4.61
A28: 51 | B28: 260210_gamme_B_7bis | D28: 10.19 | E28: Standard | F28: 3036 | H28: bbXIO | J28: 53950524 | K28: 2867447 | L28: 3417.9 | M28: 11708585 | N28: 217013.2 | O28: 4.61
A29: 52 | B29: 260210_gamme_B_8 | D29: 10.19 | E29: Standard | F29: 5060 | H29: bbXIO | J29: 75593704 | K29: 2720233 | L29: 5048.23 | M29: 16597652 | N29: 1019583936 | O29: 4.55
A30: 12 | B30: 260210_MeOH_1 | D30: 10.19 | H30: bb | J30: 38112 | K30: 1320 | M30: 7899 | N30: 308.5 | O30: 4.83
A31: 13 | B31: 260210_MeOH_2 | D31: 10.19 | H31: bb | J31: 11795 | K31: 636 | M31: 2517 | N31: 291.1 | O31: 4.69
A32: 14 | B32: 260210_blanc_1 | D32: 10.19 | H32: bb | J32: 8905 | K32: 557 | M32: 2382 | N32: 317.4 | O32: 3.74
A33: 15 | B33: 260210_blanc_2 | D33: 10.19 | H33: bb | J33: 6458 | K33: 460 | M33: 1449 | N33: 491.5 | O33: 4.46 | Q33: dilution | R33: pe en g | S33: quantité ng | T33: ng/g de vdt
A34: 16 | B34: 260210_Si_vdt_dil | D34: 10.19 | H34: bb | I34: 0.422 | J34: 5249 | K34: 3612793 | L34: 0.34 | M34: 4952 | N34: 297 | O34: 1.06 | Q34: 60000 | U34: effet mémoire, aire similaire blancs précédents
A35: 17 | B35: 260210_vdt_N0_1_dil20 | C35: tube 19 | D35: 10.19 | H35: bb | I35: 0.718 | J35: 11490 | K35: 2615102 | L35: 0.8 | M35: 4541 | N35: 634.2 | O35: 2.53 | Q35: 20 | R35: 0.2771 | S35: =((I35*Q35*1.5)/1000)*(6/0.1)*1.296 -> 1.6749504 | T35: =S35/R35 -> 6.0445702
A36: 18 | B36: 260210_vdt_N0_2_dil20 | C36: tube 20 | D36: 10.19 | H36: bb | I36: 0.713 | J36: 11825 | K36: 2716141 | L36: 0.79 | M36: 4663 | N36: 799.3 | O36: 2.54 | Q36: 20 | R36: 0.2948 | S36: =((I36*Q36*1.5)/1000)*(6/0.1)*1.296 -> 1.6632864 | T36: =S36/R36 -> 5.6420841
A37: 19 | B37: 260210_epx_J0_25_1 | C37: tube 1 | D37: 10.19 | H37: bb | I37: 47.722 | J37: 963915 | K37: 2408070 | L37: 72.7 | M37: 199599 | N37: 36180.4 | O37: 4.83 | Q37: 20 | R37: 0.2902 | S37: =((I37*Q37*1.5)/1000)*(6/0.1)*1.296 -> 111.32588 | T37: =S37/R37 -> 383.61779
A38: 20 | B38: 260210_epx_J0_25_2 | C38: tube 2 | D38: 10.19 | H38: bb | I38: 51.494 | J38: 1099291 | K38: 2545794 | L38: 78.42 | M38: 224496 | N38: 65584.1 | O38: 4.9 | Q38: 20 | R38: 0.3361 | S38: =((I38*Q38*1.5)/1000)*(6/0.1)*1.296 -> 120.1252 | T38: =S38/R38 -> 357.40911
A39: 21 | B39: 260210_epx_J0_25_3 | C39: tube3 | D39: 10.19 | H39: bb | I39: 41.262 | J39: 856451 | K39: 2473738 | L39: 62.88 | M39: 176665 | N39: 4022 | O39: 4.85 | Q39: 20 | R39: 0.2835 | S39: =((I39*Q39*1.5)/1000)*(6/0.1)*1.296 -> 96.255994 | T39: =S39/R39 -> 339.52731
A40: 22 | B40: 260210_epx_J1_1 | C40: tube 4 | D40: 10.19 | H40: bb | I40: 103.226 | J40: 2061384 | K40: 2395953 | L40: 156.26 | M40: 428558 | N40: 53420.8 | O40: 4.81 | Q40: 20 | R40: 0.2841 | S40: =((I40*Q40*1.5)/1000)*(6/0.1)*1.296 -> 240.80561 | T40: =S40/R40 -> 847.60863
A41: 23 | B41: 260210_epx_J1_2 | C41: tube 5 | D41: 10.19 | H41: bb | I41: 64.581 | J41: 1324380 | K41: 2448548 | L41: 98.24 | M41: 271903 | N41: 24902.3 | O41: 4.87 | Q41: 20 | R41: 0.3084 | S41: =((I41*Q41*1.5)/1000)*(6/0.1)*1.296 -> 150.65456 | T41: =S41/R41 -> 488.50375
A42: 24 | B42: 260210_epx_J1_3 | C42: tube 6 | D42: 10.19 | H42: bb | I42: 108.503 | J42: 2115625 | K42: 2341092 | L42: 164.13 | M42: 431786 | N42: 102345.4 | O42: 4.9 | Q42: 20 | R42: 0.3005 | S42: =((I42*Q42*1.5)/1000)*(6/0.1)*1.296 -> 253.1158 | T42: =S42/R42 -> 842.31547
A43: 25 | B43: 260210_epx_J3_1 | C43: tube 7 | D43: 10.19 | H43: bb | I43: 78.386 | J43: 1587173 | K43: 2421494 | L43: 119.04 | M43: 330343 | N43: 101405.3 | O43: 4.8 | Q43: 20 | R43: 0.2911 | S43: =((I43*Q43*1.5)/1000)*(6/0.1)*1.296 -> 182.85886 | T43: =S43/R43 -> 628.1651
...

Sheet résultats
B1: ng/g de vers de terre frais
B2: Epoxiconazole | C2: Imidaclopride
A3: vdt_N0_1 | B3: ='260210_tese Lisa_vdt_TKbis'!T35 -> 6.0445702 | C3: ='260210_tese Lisa_vdt_TKbis'!T147 -> 6.692804
A4: vdt_N0_2 | B4: ='260210_tese Lisa_vdt_TKbis'!T36 -> 5.6420841 | C4: ='260210_tese Lisa_vdt_TKbis'!T148 -> 5.7053894
A6: epx_J0_25_1 | B6: ='260210_tese Lisa_vdt_TKbis'!T37 -> 383.61779 | C6: ='260210_tese Lisa_vdt_TKbis'!T149 -> 7.7652819
A7: epx_J0_25_2 | B7: ='260210_tese Lisa_vdt_TKbis'!T38 -> 357.40911 | C7: ='260210_tese Lisa_vdt_TKbis'!T150 -> 4.0325998
A8: epx_J0_25_3 | B8: ='260210_tese Lisa_vdt_TKbis'!T39 -> 339.52731 | C8: ='260210_tese Lisa_vdt_TKbis'!T151 -> 11.314286
A10: epx_J1_1 | B10: ='260210_tese Lisa_vdt_TKbis'!T40 -> 847.60863 | C10: ='260210_tese Lisa_vdt_TKbis'!T152 -> 8.3589947
A11: epx_J1_2 | B11: ='260210_tese Lisa_vdt_TKbis'!T41 -> 488.50375 | C11: ='260210_tese Lisa_vdt_TKbis'!T153 -> 7.178428
A12: epx_J1_3 | B12: ='260210_tese Lisa_vdt_TKbis'!T42 -> 842.31547 | C12: ='260210_tese Lisa_vdt_TKbis'!T154 -> 5.0615161
A14: epx_J3_1 | B14: ='260210_tese Lisa_vdt_TKbis'!T43 -> 628.1651 | C14: ='260210_tese Lisa_vdt_TKbis'!T155 -> 21.124221
A15: epx_J3_2 | B15: ='260210_tese Lisa_vdt_TKbis'!T44 -> 683.90907 | C15: ='260210_tese Lisa_vdt_TKbis'!T156 -> 5.7639533
A16: epx_J3_3 | B16: ='260210_tese Lisa_vdt_TKbis'!T45 -> 569.11821 | C16: ='260210_tese Lisa_vdt_TKbis'!T157 -> 5.0700302
A18: imd_J3_1 | B18: ='260210_tese Lisa_vdt_TKbis'!T47 -> 5.644482 | C18: ='260210_tese Lisa_vdt_TKbis'!T159 -> 632.44716
A19: imd_J3_2 | B19: ='260210_tese Lisa_vdt_TKbis'!T48 -> 3.3082367 | C19: ='260210_tese Lisa_vdt_TKbis'!T160 -> 571.05187
A20: imd_J3_3 | B20: ='260210_tese Lisa_vdt_TKbis'!T49 -> 3.3163636 | C20: ='260210_tese Lisa_vdt_TKbis'!T161 -> 721.37891
A22: imd_J7_1 | B22: ='260210_tese Lisa_vdt_TKbis'!T50 -> 6.2248973 | C22: ='260210_tese Lisa_vdt_TKbis'!T162 -> 757.25129
A23: imd_J7_2 | B23: ='260210_tese Lisa_vdt_TKbis'!T51 -> 3.3093432 | C23: ='260210_tese Lisa_vdt_TKbis'!T163 -> 949.76236
A24: imd_J7_3 | B24: ='260210_tese Lisa_vdt_TKbis'!T52 -> 3.402443 | C24: ='260210_tese Lisa_vdt_TKbis'!T164 -> 900.55224
A26: imd_J14_1 | B26: ='260210_tese Lisa_vdt_TKbis'!T53 -> 3.0300845 | C26: ='260210_tese Lisa_vdt_TKbis'!T165 -> 1319.6201
A27: imd_J14_2 | B27: ='260210_tese Lisa_vdt_TKbis'!T54 -> 3.586279 | C27: ='260210_tese Lisa_vdt_TKbis'!T166 -> 860.11115
A28: imd_J14_3 | B28: ='260210_tese Lisa_vdt_TKbis'!T55 -> 3.0517132 | C28: ='260210_tese Lisa_vdt_TKbis'!T167 -> 1208.8208
