Workbook

Sheet facteur récupération
A1: Données | B1: Valeur
A2: extraction 1
A3: V acn ajouté ml | B3: 5
A4: V acn récupéré ml | B4: 3
A5: % récupéré | B5: =B4*100/B3 -> 60
A6: extraction 2
A7: V acn restant de 1 | B7: =B3-B4 -> 2
A8: V acn ajouté ml | B8: 5
A9: V acn récupéré | B9: 3
A10: % récupéré | B10: =((B3-B4)/B3)*B9*100/(B8+B7) -> 17.142857
A11: V extrait (1+2) ml | B11: =B9+B4 -> 6
A12: % récupéré e1 + e2 | B12: =B5+B10 -> 77.142857
A13: facteur de correction pour 100 % | B13: =100/B12 -> 1.2962963

Sheet 260212_these Lisa_VDT_MIX sprin
A1: Quantify Compound Summary Report
A3: Printed Mon Feb 16 08:16:02 2026
A5: Compound 1: epoxiconazole
B7: Name | C7: Sample Text | D7: RT | E7: Type | F7: Std , Conc | G7: %Dev | H7: Primary Flags | I7: ng/l | J7: Area | K7: IS Area | L7: Response | M7: 1ｺ Area | N7: S/N | O7: 1ｺ Ratio (Actual)
A8: 1 | B8: 260212_gamme_A_0 | D8: 10 ,20 | E8: Standard | F8: 0 ,250 | H8: bbXI | J8: 10428 | K8: 3962877 | L8: 0 ,48 | M8: 6402 | N8: 312 ,6 | O8: 1 ,63
A9: 2 | B9: 260212_gamme_A_1 | D9: 10 ,20 | E9: Standard | F9: 4 ,050 | G9: -15.1 | H9: bb | I9: 3.44 | J9: 122804 | K9: 3964507 | L9: 5 ,63 | M9: 29250 | N9: 2821 ,7 | O9: 4 ,20
A10: 3 | B10: 260212_gamme_A_1bis | D10: 10 ,19 | E10: Standard | F10: 4 ,050 | G10: -13.1 | H10: bb | I10: 3.519 | J10: 119693 | K10: 3793412 | L10: 5 ,73 | M10: 28296 | N10: 4153 ,7 | O10: 4 ,23
A11: 4 | B11: 260212_gamme_A_2 | D11: 10 ,20 | E11: Standard | F11: 14 ,170 | G11: -1.9 | H11: bb | I11: 13.894 | J11: 403030 | K11: 3747721 | L11: 19 ,54 | M11: 84280 | N11: 7567 ,5 | O11: 4 ,78
A12: 5 | B12: 260212_gamme_A_2bis | D12: 10 ,20 | E12: Standard | F12: 14 ,170 | G12: 0 | H12: bb | I12: 14.165 | J12: 405450 | K12: 3702092 | L12: 19 ,90 | M12: 84368 | N12: 7908 ,4 | O12: 4 ,81
A13: 6 | B13: 260212_gamme_A_3 | D13: 10 ,20 | E13: Standard | F13: 80 ,960 | G13: 7.6 | H13: bb | I13: 87.109 | J13: 2366355 | K13: 3690652 | L13: 116 ,48 | M13: 463431 | N13: 101827 ,1 | O13: 5 ,11
A14: 7 | B14: 260212_gamme_A_4 | D14: 10 ,20 | E14: Standard | F14: 161 ,920 | G14: 4.2 | H14: bb | I14: 168.646 | J14: 4639020 | K14: 3770916 | L14: 223 ,48 | M14: 917882 | N14: 86480 ,7 | O14: 5 ,05
A15: 8 | B15: 260212_gamme_A_5 | D15: 10 ,20 | E15: Standard | F15: 404 ,800 | G15: 3.1 | H15: bb | I15: 417.206 | J15: 11333257 | K15: 3788245 | L15: 543 ,47 | M15: 2235375 | N15: 175409 ,1 | O15: 5 ,07
A16: 9 | B16: 260212_gamme_A_6 | D16: 10 ,20 | E16: Standard | F16: 1012 ,000 | G16: -1 | H16: bb | I16: 1001.709 | J16: 25536964 | K16: 3684350 | L16: 1259 ,12 | M16: 5249654 | N16: 440210 ,9 | O16: 4 ,86
A17: 10 | B17: 260212_gamme_A_7 | D17: 10 ,20 | E17: Standard | F17: 3036 ,000 | G17: -3.4 | H17: bb | I17: 2932.869 | J17: 60506916 | K17: 3375659 | L17: 3256 ,16 | M17: 12992424 | N17: 5895260 ,1 | O17: 4 ,66
A18: 11 | B18: 260212_gamme_A_8 | D18: 10 ,20 | E18: Standard | F18: 5060 ,000 | G18: -0.3 | H18: bb | I18: 5047.146 | J18: 84528480 | K18: 3201933 | L18: 4795 ,68 | M18: 18900666 | N18: 1136140672 ,0 | O18: 4 ,47
A19: 67 | B19: 260212_gamme_B_0 | D19: 10 ,19 | E19: Standard | F19: 0 ,250 | H19: bbXI | J19: 17114 | K19: 3528144 | L19: 0 ,88 | M19: 6815 | N19: 308 ,6 | O19: 2 ,51
A20: 68 | B20: 260212_gamme_B_1 | D20: 10 ,19 | E20: Standard | F20: 4 ,050 | G20: -6.2 | H20: bb | I20: 3.8 | J20: 127316 | K20: 3787349 | L20: 6 ,11 | M20: 29290 | N20: 1229 ,3 | O20: 4 ,35
A21: 69 | B21: 260212_gamme_B_2 | D21: 10 ,20 | E21: Standard | F21: 14 ,170 | G21: 7 | H21: bb | I21: 15.163 | J21: 438778 | K21: 3755986 | L21: 21 ,22 | M21: 89621 | N21: 8565 ,8 | O21: 4 ,90
A22: 70 | B22: 260212_gamme_B_3 | D22: 10 ,20 | E22: Standard | F22: 80 ,960 | G22: 7.8 | H22: bb | I22: 87.289 | J22: 2502618 | K22: 3895255 | L22: 116 ,71 | M22: 489710 | N22: 53466 ,9 | O22: 5 ,11
A23: 71 | B23: 260212_gamme_B_4 | D23: 10 ,19 | E23: Standard | F23: 161 ,920 | G23: 5.7 | H23: bb | I23: 171.136 | J23: 4856061 | K23: 3890723 | L23: 226 ,73 | M23: 950011 | N23: 262467 ,7 | O23: 5 ,11
A24: 72 | B24: 260212_gamme_B_5 | D24: 10 ,20 | E24: Standard | F24: 404 ,800 | G24: 5.4 | H24: bb | I24: 426.507 | J24: 11849335 | K24: 3876625 | L24: 555 ,26 | M24: 2345549 | N24: 3700769 ,4 | O24: 5 ,05
A25: 73 | B25: 260212_gamme_B_6 | D25: 10 ,20 | E25: Standard | F25: 1012 ,000 | G25: -0.2 | H25: bb | I25: 1009.863 | J25: 26263158 | K25: 3760399 | L25: 1268 ,74 | M25: 5385184 | N25: 395978912 ,0 | O25: 4 ,88
A26: 74 | B26: 260212_gamme_B_7 | D26: 10 ,20 | E26: Standard | F26: 3036 ,000 | G26: -2.6 | H26: bb | I26: 2958.462 | J26: 60637492 | K26: 3359546 | L26: 3278 ,84 | M26: 12987904 | N26: 845784832 ,0 | O26: 4 ,67
A27: 75 | B27: 260212_gamme_B_8 | D27: 10 ,20 | E27: Standard | F27: 5060 ,000 | G27: 3.6 | H27: bb | I27: 5243.109 | J27: 82634952 | K27: 3060984 | L27: 4904 ,13 | M27: 18177202 | N27: 1105205376 ,0 | O27: 4 ,55
A28: 12 | B28: 260212_blanc_MeOH_1 | D28: 10 ,20 | H28: bb | J28: 42408 | K28: 1766 | M28: 9103 | N28: 1079 ,3 | O28: 4 ,66
A29: 13 | B29: 260212_blanc_MeOH_2 | D29: 10 ,20 | H29: bb | J29: 11709 | K29: 601 | M29: 2603 | N29: 304 ,6 | O29: 4 ,50
A30: 14 | B30: 260212_blanc_eau_1 | D30: 10 ,20 | H30: bb | J30: 9524 | K30: 543 | M30: 2126 | N30: 118 ,1 | O30: 4 ,48
A31: 15 | B31: 260212_blanc_eau_2 | D31: 10 ,19 | H31: bb | J31: 6335 | K31: 387 | M31: 1475 | N31: 213 ,5 | O31: 4 ,29 | Q31: dilution | R31: pe en g | S31: quantité ng | T31: ng/g de vdt
A32: 16 | B32: 260212_Si_vdt_dil | D32: 10 ,19 | H32: bb | J32: 6382 | K32: 5117799 | M32: 9052 | N32: 465 ,7 | O32: 0 ,70 | Q32: 60000
A33: 17 | B33: 260212_vdt_N01_lot_D | C33: tube 42 | D33: 10 ,20 | H33: bb | I33: 117.146 | J33: 3105247 | K33: 3614948 | L33: 156 ,01 | M33: 605159 | N33: 92261 ,8 | O33: 5 ,13 | Q33: 1 | R33: 0.2917 | S33: =((I33*Q33*1.5)/1000)*(6/0.1)*1.296 -> 13.663909 | T33: =S33/R33 -> 46.842336
A34: 18 | B34: 260212_vdt_N03_lot_E | C34: tube 43 | D34: 10 ,20 | H34: bb | I34: 59.16 | J34: 1602899 | K34: 3658883 | L34: 79 ,56 | M34: 314355 | N34: 6939 ,7 | O34: 5 ,10 | Q34: 1 | R34: 0.3077 | S34: =((I34*Q34*1.5)/1000)*(6/0.1)*1.296 -> 6.9004224 | T34: =S34/R34 -> 22.425812
A35: 19 | B35: 260212_vdt_I2_3_2_dil20 | C35: tube 40 | D35: 10 ,20 | H35: bb | I35: 17.047 | J35: 491431 | K35: 3761736 | L35: 23 ,73 | M35: 99980 | N35: 26264 ,4 | O35: 4 ,92 | Q35: 20 | R35: 0.2994 | S35: =((I35*Q35*1.5)/1000)*(6/0.1)*1.296 -> 39.767242 | T35: =S35/R35 -> 132.82312
A36: 20 | B36: 260212_vdt_I2_3_1_dil20 | C36: tube 39 | D36: 10 ,20 | H36: bb | I36: 15.143 | J36: 447381 | K36: 3833422 | L36: 21 ,20 | M36: 92445 | N36: 24902 ,5 | O36: 4 ,84 | Q36: 20 | R36: 0.2941 | S36: =((I36*Q36*1.5)/1000)*(6/0.1)*1.296 -> 35.32559 | T36: =S36/R36 -> 120.11421
A37: 21 | B37: 260212_vdt_I2_1_2_dil20 | C37: tube 38 | D37: 10 ,20 | H37: bb | I37: 34.975 | J37: 1050270 | K37: 4013217 | L37: 47 ,53 | M37: 207652 | N37: 23157 ,9 | O37: 5 ,06 | Q37: 20 | R37: 0.3064 | S37: =((I37*Q37*1.5)/1000)*(6/0.1)*1.296 -> 81.58968 | T37: =S37/R37 -> 266.28486
A38: 22 | B38: 260212_vdt_I2_1_1_dil20 | C38: tube 37 | D38: 10 ,20 | H38: bb | I38: 51.159 | J38: 1549979 | K38: 4081180 | L38: 68 ,98 | M38: 303470 | N38: 32887 ,0 | O38: 5 ,11 | Q38: 20 | R38: 0.295 | S38: =((I38*Q38*1.5)/1000)*(6/0.1)*1.296 -> 119.34372 | T38: =S38/R38 -> 404.55497
A39: 23 | B39: 260212_vdt_H2_3_2_dil20 | C39: tube 36 | D39: 10 ,20 | H39: bb | I39: 83.82 | J39: 2407979 | K39: 3899976 | L39: 112 ,14 | M39: 474271 | N39: 74799 ,0 | O39: 5 ,08 | Q39: 20 | R39: 0.3104 | S39: =((I39*Q39*1.5)/1000)*(6/0.1)*1.296 -> 195.5353 | T39: =S39/R39 -> 629.94619
A40: 24 | B40: 260212_vdt_H2_3_1_dil20 | C40: tube 35 | D40: 10 ,20 | H40: bb | I40: 110.944 | J40: 2987919 | K40: 3670140 | L40: 147 ,86 | M40: 582760 | N40: 271088 ,0 | O40: 5 ,13 | Q40: 20 | R40: 0.3104 | S40: =((I40*Q40*1.5)/1000)*(6/0.1)*1.296 -> 258.81016 | T40: =S40/R40 -> 833.79563
A41: 25 | B41: 260212_vdt_H2_1_2_dil20 | C41: tube 34 | D41: 10 ,20 | H41: bb | I41: 72.759 | J41: 2067102 | K41: 3848983 | L41: 97 ,54 | M41: 403568 | N41: 113351 ,5 | O41: 5 ,12 | Q41: 20 | R41: 0.3027 | S41: =((I41*Q41*1.5)/1000)*(6/0.1)*1.296 -> 169.7322 | T41: =S41/R41 -> 560.72744
A42: 26 | B42: 260212_vdt_H2_1_1_dil20 | C42: tube 33 | D42: 10 ,20 | H42: bb | I42: 83.726 | J42: 2404668 | K42: 3898925 | L42: 112 ,01 | M42: 469907 | N42: 389940 ,1 | O42: 5 ,12 | Q42: 20 | R42: 0.299 | S42: =((I42*Q42*1.5)/1000)*(6/0.1)*1.296 -> 195.31601 | T42: =S42/R42 -> 653.23081
A43: 27 | B43: 260212_vdt_G2_3_2_dil20 | C43: tube 32 | D43: 10 ,20 | H43: bb | I43: 1740.974 | J43: 40710988 | K43: 3537350 | L43: 2090 ,25 | M43: 8592478 | N43: 589271296 ,0 | O43: 4 ,74 | Q43: 20 | R43: 0.3001 | S43: =((I43*Q43*1.5)/1000)*(6/0.1)*1.296 -> 4061.3441 | T43: =S43/R43 -> 13533.303
...

Sheet résultats
B1: ng/g de vers de terre frais
B2: Epoxiconazole | C2: Imidaclopride
A3: vdt_N01_lot_D | B3: ='260212_these Lisa_VDT_MIX sprin'!T33 -> 46.842336 | C3: ='260212_these Lisa_VDT_MIX sprin'!T191 -> 4.1249854
A4: vdt_N03_lot_E | B4: ='260212_these Lisa_VDT_MIX sprin'!T34 -> 22.425812 | C4: ='260212_these Lisa_VDT_MIX sprin'!T192 -> 3.4544697
A6: vdt_I2_3_2 | B6: ='260212_these Lisa_VDT_MIX sprin'!T35 -> 132.82312 | C6: ='260212_these Lisa_VDT_MIX sprin'!T233 -> 506.18955
A7: vdt_I2_3_1 | B7: ='260212_these Lisa_VDT_MIX sprin'!T36 -> 120.11421 | C7: ='260212_these Lisa_VDT_MIX sprin'!T234 -> 558.14441
A8: vdt_I2_1_2 | B8: ='260212_these Lisa_VDT_MIX sprin'!T37 -> 266.28486 | C8: ='260212_these Lisa_VDT_MIX sprin'!T235 -> 482.37112
A9: vdt_I2_1_1 | B9: ='260212_these Lisa_VDT_MIX sprin'!T38 -> 404.55497 | C9: ='260212_these Lisa_VDT_MIX sprin'!T236 -> 452.06422
A11: vdt_H2_3_2 | B11: ='260212_these Lisa_VDT_MIX sprin'!T39 -> 629.94619 | C11: ='260212_these Lisa_VDT_MIX sprin'!T229 -> 468.05896
A12: vdt_H2_3_1 | B12: ='260212_these Lisa_VDT_MIX sprin'!T40 -> 833.79563 | C12: ='260212_these Lisa_VDT_MIX sprin'!T230 -> 541.07244
A13: vdt_H2_1_2 | B13: ='260212_these Lisa_VDT_MIX sprin'!T41 -> 560.72744 | C13: ='260212_these Lisa_VDT_MIX sprin'!T231 -> 283.47104
A14: vdt_H2_1_1 | B14: ='260212_these Lisa_VDT_MIX sprin'!T42 -> 653.23081 | C14: ='260212_these Lisa_VDT_MIX sprin'!T232 -> 327.80014
A16: vdt_G2_3_2 | B16: ='260212_these Lisa_VDT_MIX sprin'!T43 -> 13533.303 | C16: ='260212_these Lisa_VDT_MIX sprin'!T225 -> 326.86174
A17: vdt_G2_3_1 | B17: ='260212_these Lisa_VDT_MIX sprin'!T44 -> 18465.344 | C17: ='260212_these Lisa_VDT_MIX sprin'!T226 -> 310.08959
A18: vdt_G2_1_2 | B18: ='260212_these Lisa_VDT_MIX sprin'!T45 -> 1219.958 | C18: ='260212_these Lisa_VDT_MIX sprin'!T227 -> 330.50956
A19: vdt_G2_1_1 | B19: ='260212_these Lisa_VDT_MIX sprin'!T46 -> 681.62694 | C19: ='260212_these Lisa_VDT_MIX sprin'!T228 -> 244.66803
A21: vdt_F2_3_2 | B21: ='260212_these Lisa_VDT_MIX sprin'!T47 -> 1938.0576 | C21: ='260212_these Lisa_VDT_MIX sprin'!T221 -> 155.68325
A22: vdt_F2_3_1 | B22: ='260212_these Lisa_VDT_MIX sprin'!T48 -> 2168.2445 | C22: ='260212_these Lisa_VDT_MIX sprin'!T222 -> 155.72116
A23: vdt_F2_1_2 | B23: ='260212_these Lisa_VDT_MIX sprin'!T49 -> 1415.1552 | C23: ='260212_these Lisa_VDT_MIX sprin'!T223 -> 159.76448
A24: vdt_F2_1_1 | B24: ='260212_these Lisa_VDT_MIX sprin'!T50 -> 1755.8317 | C24: ='260212_these Lisa_VDT_MIX sprin'!T224 -> 159.54956
A26: vdt_E2_3_2 | B26: ='260212_these Lisa_VDT_MIX sprin'!T51 -> 2859.0937 | C26: ='260212_these Lisa_VDT_MIX sprin'!T217 -> 3.4146065
A27: vdt_E2_3_1 | B27: ='260212_these Lisa_VDT_MIX sprin'!T52 -> 2730.0492 | C27: ='260212_these Lisa_VDT_MIX sprin'!T218 -> 3.3258056
A28: vdt_E2_1_2 | B28: ='260212_these Lisa_VDT_MIX sprin'!T53 -> 1761.5806 | C28: ='260212_these Lisa_VDT_MIX sprin'!T219 -> 19.307823
A29: vdt_E2_1_1 | B29: ='260212_these Lisa_VDT_MIX sprin'!T54 -> 2061.7131 | C29: ='260212_these Lisa_VDT_MIX sprin'!T220 -> 23.603189
A31: vdt_E5_3_2 | B31: ='260212_these Lisa_VDT_MIX sprin'!T55 -> 41739.931 | C31: ='260212_these Lisa_VDT_MIX sprin'!T216 -> 4.0339994
